Workbook

Sheet Intro
A1: THIS IS A VIEW-ONLY EXCEL SHEET.
A2: DOWNLOAD THIS SHEET (FILE -> DOWNLOAD AS XLSX) AND THEN USE IT ON YOUR OWN
A4: This sheet has been prepared by Ankur Warikoo, who is NOT a financial advisor :)
A5: So use this sheet with your judgement and not like "this is my final decision"
A7: All cells in green are input cells, which means you have to put in the number
A8: All other cells - ideally you should not touch them. But I have kept them open, so that you can see the formula and how it works
A10: NOTE:
A11: Since I am not a financial advisor, there could be some errors in the sheet. If there are, send me an email and I will fix them. Simple :)
A13: Hope you find this useful.

Sheet How much will I make
A1: Current Age | C1: 20
A2: Retirement Age | C2: 60
A3: Monthly Contributions | C3: 500
A4: Yearly increase in contribution | C4: 0.05
A5: Inflation | C5: 0.05
B7: If you make this return | C7: Your bank will show this amount | D7: But, adjusted for inflation this amount will be equal to? | E7: In other words, at the end of your retirement age, you will have
B8: 5% - FD returns | C8: =VLOOKUP(Calculations!$B$1*12,Calculations!A4:AH654,4,0) -> 1682565.6 | D8: =VLOOKUP(Calculations!$B$1*12,Calculations!A4:AH654,6,0) -> 724798.65 | E8: =D8/10000000 -> 0.072479865 | F8: Crores (in today's money) to spend
B9: 10% - Gold returns | C9: =VLOOKUP(Calculations!$B$1*12,Calculations!A5:AH655,8,0) -> 5358115.6 | D9: =VLOOKUP(Calculations!$B$1*12,Calculations!A5:AH655,10,0) -> 1675594 | E9: =D9/10000000 -> 0.1675594 | F9: Crores (in today's money) to spend
B10: 15% - Equity returns | C10: =VLOOKUP(Calculations!$B$1*12,Calculations!A6:AH656,12,0) -> 22158439 | D10: =VLOOKUP(Calculations!$B$1*12,Calculations!A6:AH656,14,0) -> 5300464.4 | E10: =D10/10000000 -> 0.53004644 | F10: Crores (in today's money) to spend
B11: 20% - High risk equity returns | C11: =VLOOKUP(Calculations!$B$1*12,Calculations!A7:AH657,16,0) -> 1.0816166e+08 | D11: =VLOOKUP(Calculations!$B$1*12,Calculations!A7:AH657,18,0) -> 21744087 | E11: =D11/10000000 -> 2.1744087 | F11: Crores (in today's money) to spend
B12: 25% - very hard to get | C12: =VLOOKUP(Calculations!$B$1*12,Calculations!A8:AH658,20,0) -> 5.8018447e+08 | D12: =VLOOKUP(Calculations!$B$1*12,Calculations!A8:AH658,22,0) -> 1.0525593e+08 | E12: =D12/10000000 -> 10.525593 | F12: Crores (in today's money) to spend
B13: 30% - extremely risky | C13: =VLOOKUP(Calculations!$B$1*12,Calculations!A9:AH659,24,0) -> 3.2846146e+09 | D13: =VLOOKUP(Calculations!$B$1*12,Calculations!A9:AH659,26,0) -> 5.5995143e+08 | E13: =D13/10000000 -> 55.995143 | F13: Crores (in today's money) to spend
B14: 35% - almost impossible | C14: =VLOOKUP(Calculations!$B$1*12,Calculations!A10:AH660,28,0) -> 1.9204951e+10 | D14: =VLOOKUP(Calculations!$B$1*12,Calculations!A10:AH660,30,0) -> 3.1444248e+09 | E14: =D14/10000000 -> 314.44248 | F14: Crores (in today's money) to spend
B15: 40% - forget it :) | C15: =VLOOKUP(Calculations!$B$1*12,Calculations!A11:AH661,32,0) -> 1.1456493e+11 | D15: =VLOOKUP(Calculations!$B$1*12,Calculations!A11:AH661,34,0) -> 1.8238751e+10 | E15: =D15/10000000 -> 1823.8751 | F15: Crores (in today's money) to spend

Sheet Calculations
A1: Period | B1: ='How much will I make'!C2-'How much will I make'!C1 -> 40
C3: 0.05 | G3: 0.1 | K3: 0.15 | O3: 0.2 | S3: 0.25 | W3: 0.3 | AA3: 0.35 | AE3: 0.4
A4: Month | B4: Monthly | C4: FV | D4: Cum FV | E4: NPV | F4: Cum | G4: FV | H4: Cum FV | I4: NPV | J4: Cum | K4: FV | L4: Cum FV | M4: NPV | N4: Cum | O4: FV | P4: Cum FV | Q4: NPV | R4: Cum | S4: FV | T4: Cum FV | U4: NPV | V4: Cum | W4: FV | X4: Cum FV | Y4: NPV | Z4: Cum | AA4: FV | AB4: Cum FV | AC4: NPV | AD4: Cum | AE4: FV | AF4: Cum FV | AG4: NPV | AH4: Cum
A5: 1 | B5: ='How much will I make'!C3 -> 500 | C5: =$B5*(1+$C$3/12)^($B$1*12-$A5) -> 3663.9422 | D5: =C5 -> 3663.9422 | E5: =C$5/((1+'How much will I make'!$C$5/12)^(Calculations!$B$1*12-Calculations!$A5)) -> 500 | F5: =E5 -> 500 | G5: =$B5*(1+G$3/12)^($B$1*12-$A5) -> 26628.428 | H5: =G5 -> 26628.428 | I5: =G5/((1+'How much will I make'!$C$5/12)^(Calculations!$B$1*12-Calculations!$A5)) -> 3633.8493 | J5: =I5 -> 3633.8493 | K5: =$B5*(1+K$3/12)^($B$1*12-$A5) -> 191950.96 | L5: =K5 -> 191950.96 | M5: =K5/((1+'How much will I make'!$C$5/12)^(Calculations!$B$1*12-Calculations!$A5)) -> 26194.594 | N5: =M5 -> 26194.594 | O5: =$B5*(1+O$3/12)^($B$1*12-$A5) -> 1372499 | P5: =O5 -> 1372499 | Q5: =O5/((1+'How much will I make'!$C$5/12)^(Calculations!$B$1*12-Calculations!$A5)) -> 187298.12 | R5: =Q5 -> 187298.12 | S5: =$B5*(1+S$3/12)^($B$1*12-$A5) -> 9735082.5 | T5: =S5 -> 9735082.5 | U5: =S5/((1+'How much will I make'!$C$5/12)^(Calculations!$B$1*12-Calculations!$A5)) -> 1328498.4 | V5: =U5 -> 1328498.4 | W5: =$B5*(1+W$3/12)^($B$1*12-$A5) -> 68501728 | X5: =W5 -> 68501728 | Y5: =W5/((1+'How much will I make'!$C$5/12)^(Calculations!$B$1*12-Calculations!$A5)) -> 9348090.6 | Z5: =Y5 -> 9348090.6 | AA5: =$B5*(1+AA$3/12)^($B$1*12-$A5) -> 4.7821791e+08 | AB5: =AA5 -> 4.7821791e+08 | AC5: =AA5/((1+'How much will I make'!$C$5/12)^(Calculations!$B$1*12-Calculations!$A5)) -> 65260023 | AD5: =AC5 -> 65260023 | AE5: =$B5*(1+AE$3/12)^($B$1*12-$A5) -> 3.3123814e+09 | AF5: =AE5 -> 3.3123814e+09 | AG5: =AE5/((1+'How much will I make'!$C$5/12)^(Calculations!$B$1*12-Calculations!$A5)) -> 4.5202424e+08 | AH5: =AG5 -> 4.5202424e+08
A6: =A5+1 -> 2 | B6: =B5 -> 500 | C6: =$B6*(1+$C$3/12)^($B$1*12-$A6) -> 3648.7392 | D6: =C6+D5 -> 7312.6814 | E6: =$C6/((1+'How much will I make'!$C$5/12)^(Calculations!$B$1*12-Calculations!$A6)) -> 500 | F6: =E6+F5 -> 1000 | G6: =$B6*(1+G$3/12)^($B$1*12-$A6) -> 26408.358 | H6: =G6+H5 -> 53036.786 | I6: =G6/((1+'How much will I make'!$C$5/12)^(Calculations!$B$1*12-Calculations!$A6)) -> 3618.8334 | J6: =I6+J5 -> 7252.6827 | K6: =$B6*(1+K$3/12)^($B$1*12-$A6) -> 189581.19 | L6: =K6+L5 -> 381532.15 | M6: =K6/((1+'How much will I make'!$C$5/12)^(Calculations!$B$1*12-Calculations!$A6)) -> 25979 | N6: =M6+N5 -> 52173.594 | O6: =$B6*(1+O$3/12)^($B$1*12-$A6) -> 1349999 | P6: =O6+P5 -> 2722498 | Q6: =O6/((1+'How much will I make'!$C$5/12)^(Calculations!$B$1*12-Calculations!$A6)) -> 184995.28 | R6: =Q6+R5 -> 372293.4 | S6: =$B6*(1+S$3/12)^($B$1*12-$A6) -> 9536407.3 | T6: =S6+T5 -> 19271490 | U6: =S6/((1+'How much will I make'!$C$5/12)^(Calculations!$B$1*12-Calculations!$A6)) -> 1306808.6 | V6: =U6+V5 -> 2635306.9 | W6: =$B6*(1+W$3/12)^($B$1*12-$A6) -> 66830954 | X6: =W6+X5 -> 1.3533268e+08 | Y6: =W6/((1+'How much will I make'!$C$5/12)^(Calculations!$B$1*12-Calculations!$A6)) -> 9158088.8 | Z6: =Y6+Z5 -> 18506179 | AA6: =$B6*(1+AA$3/12)^($B$1*12-$A6) -> 4.6466517e+08 | AB6: =AA6+AB5 -> 9.4288308e+08 | AC6: =AA6/((1+'How much will I make'!$C$5/12)^(Calculations!$B$1*12-Calculations!$A6)) -> 63674759 | AD6: =AC6+AD5 -> 1.2893478e+08 | AE6: =$B6*(1+AE$3/12)^($B$1*12-$A6) -> 3.2055304e+09 | AF6: =AE6+AF5 -> 6.5179118e+09 | AG6: =AE6/((1+'How much will I make'!$C$5/12)^(Calculations!$B$1*12-Calculations!$A6)) -> 4.3926549e+08 | AH6: =AG6+AH5 -> 8.9128974e+08
A7: =A6+1 -> 3 | B7: =B6 -> 500 | C7: =$B7*(1+$C$3/12)^($B$1*12-$A7) -> 3633.5992 | D7: =C7+D6 -> 10946.281 | E7: =$C7/((1+'How much will I make'!$C$5/12)^(Calculations!$B$1*12-Calculations!$A7)) -> 500 | F7: =E7+F6 -> 1500 | G7: =$B7*(1+G$3/12)^($B$1*12-$A7) -> 26190.107 | H7: =G7+H6 -> 79226.894 | I7: =G7/((1+'How much will I make'!$C$5/12)^(Calculations!$B$1*12-Calculations!$A7)) -> 3603.8796 | J7: =I7+J6 -> 10856.562 | K7: =$B7*(1+K$3/12)^($B$1*12-$A7) -> 187240.68 | L7: =K7+L6 -> 568772.83 | M7: =K7/((1+'How much will I make'!$C$5/12)^(Calculations!$B$1*12-Calculations!$A7)) -> 25765.181 | N7: =M7+N6 -> 77938.775 | O7: =$B7*(1+O$3/12)^($B$1*12-$A7) -> 1327867.9 | P7: =O7+P6 -> 4050365.9 | Q7: =O7/((1+'How much will I make'!$C$5/12)^(Calculations!$B$1*12-Calculations!$A7)) -> 182720.75 | R7: =Q7+R6 -> 555014.15 | S7: =$B7*(1+S$3/12)^($B$1*12-$A7) -> 9341786.8 | T7: =S7+T6 -> 28613277 | U7: =S7/((1+'How much will I make'!$C$5/12)^(Calculations!$B$1*12-Calculations!$A7)) -> 1285472.9 | V7: =U7+V6 -> 3920779.9 | W7: =$B7*(1+W$3/12)^($B$1*12-$A7) -> 65200931 | X7: =W7+X6 -> 2.0053361e+08 | Y7: =W7/((1+'How much will I make'!$C$5/12)^(Calculations!$B$1*12-Calculations!$A7)) -> 8971948.8 | Z7: =Y7+Z6 -> 27478128 | AA7: =$B7*(1+AA$3/12)^($B$1*12-$A7) -> 4.5149653e+08 | AB7: =AA7+AB6 -> 1.3943796e+09 | AC7: =AA7/((1+'How much will I make'!$C$5/12)^(Calculations!$B$1*12-Calculations!$A7)) -> 62128004 | AD7: =AC7+AD6 -> 1.9106279e+08 | AE7: =$B7*(1+AE$3/12)^($B$1*12-$A7) -> 3.1021262e+09 | AF7: =AE7+AF6 -> 9.620038e+09 | AG7: =AE7/((1+'How much will I make'!$C$5/12)^(Calculations!$B$1*12-Calculations!$A7)) -> 4.2686687e+08 | AH7: =AG7+AH6 -> 1.3181566e+09
A8: =A7+1 -> 4 | B8: =B7 -> 500 | C8: =$B8*(1+$C$3/12)^($B$1*12-$A8) -> 3618.522 | D8: =C8+D7 -> 14564.803 | E8: =$C8/((1+'How much will I make'!$C$5/12)^(Calculations!$B$1*12-Calculations!$A8)) -> 500 | F8: =E8+F7 -> 2000 | G8: =$B8*(1+G$3/12)^($B$1*12-$A8) -> 25973.66 | H8: =G8+H7 -> 105200.55 | I8: =G8/((1+'How much will I make'!$C$5/12)^(Calculations!$B$1*12-Calculations!$A8)) -> 3588.9875 | J8: =I8+J7 -> 14445.55 | K8: =$B8*(1+K$3/12)^($B$1*12-$A8) -> 184929.07 | L8: =K8+L7 -> 753701.9 | M8: =K8/((1+'How much will I make'!$C$5/12)^(Calculations!$B$1*12-Calculations!$A8)) -> 25553.122 | N8: =M8+N7 -> 103491.9 | O8: =$B8*(1+O$3/12)^($B$1*12-$A8) -> 1306099.6 | P8: =O8+P7 -> 5356465.5 | Q8: =O8/((1+'How much will I make'!$C$5/12)^(Calculations!$B$1*12-Calculations!$A8)) -> 180474.18 | R8: =Q8+R7 -> 735488.33 | S8: =$B8*(1+S$3/12)^($B$1*12-$A8) -> 9151138.1 | T8: =S8+T7 -> 37764415 | U8: =S8/((1+'How much will I make'!$C$5/12)^(Calculations!$B$1*12-Calculations!$A8)) -> 1264485.6 | V8: =U8+V7 -> 5185265.5 | W8: =$B8*(1+W$3/12)^($B$1*12-$A8) -> 63610664 | X8: =W8+X7 -> 2.6414428e+08 | Y8: =W8/((1+'How much will I make'!$C$5/12)^(Calculations!$B$1*12-Calculations!$A8)) -> 8789592.1 | Z8: =Y8+Z7 -> 36267720 | AA8: =$B8*(1+AA$3/12)^($B$1*12-$A8) -> 4.3870108e+08 | AB8: =AA8+AB7 -> 1.8330807e+09 | AC8: =AA8/((1+'How much will I make'!$C$5/12)^(Calculations!$B$1*12-Calculations!$A8)) -> 60618822 | AD8: =AC8+AD7 -> 2.5168161e+08 | AE8: =$B8*(1+AE$3/12)^($B$1*12-$A8) -> 3.0020576e+09 | AF8: =AE8+AF7 -> 1.2622096e+10 | AG8: =AE8/((1+'How much will I make'!$C$5/12)^(Calculations!$B$1*12-Calculations!$A8)) -> 4.1481821e+08 | AH8: =AG8+AH7 -> 1.7329748e+09
A9: =A8+1 -> 5 | B9: =B8 -> 500 | C9: =$B9*(1+$C$3/12)^($B$1*12-$A9) -> 3603.5074 | D9: =C9+D8 -> 18168.31 | E9: =$C9/((1+'How much will I make'!$C$5/12)^(Calculations!$B$1*12-Calculations!$A9)) -> 500 | F9: =E9+F8 -> 2500 | G9: =$B9*(1+G$3/12)^($B$1*12-$A9) -> 25759.002 | H9: =G9+H8 -> 130959.56 | I9: =G9/((1+'How much will I make'!$C$5/12)^(Calculations!$B$1*12-Calculations!$A9)) -> 3574.157 | J9: =I9+J8 -> 18019.707 | K9: =$B9*(1+K$3/12)^($B$1*12-$A9) -> 182645.99 | L9: =K9+L8 -> 936347.89 | M9: =K9/((1+'How much will I make'!$C$5/12)^(Calculations!$B$1*12-Calculations!$A9)) -> 25342.808 | N9: =M9+N8 -> 128834.71 | O9: =$B9*(1+O$3/12)^($B$1*12-$A9) -> 1284688.1 | P9: =O9+P8 -> 6641153.6 | Q9: =O9/((1+'How much will I make'!$C$5/12)^(Calculations!$B$1*12-Calculations!$A9)) -> 178255.23 | R9: =Q9+R8 -> 913743.56 | S9: =$B9*(1+S$3/12)^($B$1*12-$A9) -> 8964380.1 | T9: =S9+T8 -> 46728795 | U9: =S9/((1+'How much will I make'!$C$5/12)^(Calculations!$B$1*12-Calculations!$A9)) -> 1243841 | V9: =U9+V8 -> 6429106.5 | W9: =$B9*(1+W$3/12)^($B$1*12-$A9) -> 62059185 | X9: =W9+X8 -> 3.2620346e+08 | Y9: =W9/((1+'How much will I make'!$C$5/12)^(Calculations!$B$1*12-Calculations!$A9)) -> 8610941.8 | Z9: =Y9+Z8 -> 44878662 | AA9: =$B9*(1+AA$3/12)^($B$1*12-$A9) -> 4.2626825e+08 | AB9: =AA9+AB8 -> 2.2593489e+09 | AC9: =AA9/((1+'How much will I make'!$C$5/12)^(Calculations!$B$1*12-Calculations!$A9)) -> 59146300 | AD9: =AC9+AD8 -> 3.1082791e+08 | AE9: =$B9*(1+AE$3/12)^($B$1*12-$A9) -> 2.905217e+09 | AF9: =AE9+AF8 -> 1.5527313e+10 | AG9: =AE9/((1+'How much will I make'!$C$5/12)^(Calculations!$B$1*12-Calculations!$A9)) -> 4.0310963e+08 | AH9: =AG9+AH8 -> 2.1360844e+09
A10: =A9+1 -> 6 | B10: =B9 -> 500 | C10: =$B10*(1+$C$3/12)^($B$1*12-$A10) -> 3588.5551 | D10: =C10+D9 -> 21756.865 | E10: =$C10/((1+'How much will I make'!$C$5/12)^(Calculations!$B$1*12-Calculations!$A10)) -> 500 | F10: =E10+F9 -> 3000 | G10: =$B10*(1+G$3/12)^($B$1*12-$A10) -> 25546.118 | H10: =G10+H9 -> 156505.67 | I10: =G10/((1+'How much will I make'!$C$5/12)^(Calculations!$B$1*12-Calculations!$A10)) -> 3559.3877 | J10: =I10+J9 -> 21579.094 | K10: =$B10*(1+K$3/12)^($B$1*12-$A10) -> 180391.1 | L10: =K10+L9 -> 1116739 | M10: =K10/((1+'How much will I make'!$C$5/12)^(Calculations!$B$1*12-Calculations!$A10)) -> 25134.226 | N10: =M10+N9 -> 153968.93 | O10: =$B10*(1+O$3/12)^($B$1*12-$A10) -> 1263627.6 | P10: =O10+P9 -> 7904781.3 | Q10: =O10/((1+'How much will I make'!$C$5/12)^(Calculations!$B$1*12-Calculations!$A10)) -> 176063.57 | R10: =Q10+R9 -> 1089807.1 | S10: =$B10*(1+S$3/12)^($B$1*12-$A10) -> 8781433.6 | T10: =S10+T9 -> 55510228 | U10: =S10/((1+'How much will I make'!$C$5/12)^(Calculations!$B$1*12-Calculations!$A10)) -> 1223533.4 | V10: =U10+V9 -> 7652639.8 | W10: =$B10*(1+W$3/12)^($B$1*12-$A10) -> 60545546 | X10: =W10+X9 -> 3.8674901e+08 | Y10: =W10/((1+'How much will I make'!$C$5/12)^(Calculations!$B$1*12-Calculations!$A10)) -> 8435922.7 | Z10: =Y10+Z9 -> 53314585 | AA10: =$B10*(1+AA$3/12)^($B$1*12-$A10) -> 4.1418778e+08 | AB10: =AA10+AB9 -> 2.6735367e+09 | AC10: =AA10/((1+'How much will I make'!$C$5/12)^(Calculations!$B$1*12-Calculations!$A10)) -> 57709547 | AD10: =AC10+AD9 -> 3.6853746e+08 | AE10: =$B10*(1+AE$3/12)^($B$1*12-$A10) -> 2.8115004e+09 | AF10: =AE10+AF9 -> 1.8338813e+10 | AG10: =AE10/((1+'How much will I make'!$C$5/12)^(Calculations!$B$1*12-Calculations!$A10)) -> 3.9173154e+08 | AH10: =AG10+AH9 -> 2.527816e+09
A11: =A10+1 -> 7 | B11: =B10 -> 500 | C11: =$B11*(1+$C$3/12)^($B$1*12-$A11) -> 3573.6648 | D11: =C11+D10 -> 25330.53 | E11: =$C11/((1+'How much will I make'!$C$5/12)^(Calculations!$B$1*12-Calculations!$A11)) -> 500 | F11: =E11+F10 -> 3500 | G11: =$B11*(1+G$3/12)^($B$1*12-$A11) -> 25334.993 | H11: =G11+H10 -> 181840.67 | I11: =G11/((1+'How much will I make'!$C$5/12)^(Calculations!$B$1*12-Calculations!$A11)) -> 3544.6795 | J11: =I11+J10 -> 25123.774 | K11: =$B11*(1+K$3/12)^($B$1*12-$A11) -> 178164.05 | L11: =K11+L10 -> 1294903 | M11: =K11/((1+'How much will I make'!$C$5/12)^(Calculations!$B$1*12-Calculations!$A11)) -> 24927.36 | N11: =M11+N10 -> 178896.29 | O11: =$B11*(1+O$3/12)^($B$1*12-$A11) -> 1242912.4 | P11: =O11+P10 -> 9147693.7 | Q11: =O11/((1+'How much will I make'!$C$5/12)^(Calculations!$B$1*12-Calculations!$A11)) -> 173898.86 | R11: =Q11+R10 -> 1263706 | S11: =$B11*(1+S$3/12)^($B$1*12-$A11) -> 8602220.7 | T11: =S11+T10 -> 64112449 | U11: =S11/((1+'How much will I make'!$C$5/12)^(Calculations!$B$1*12-Calculations!$A11)) -> 1203557.3 | V11: =U11+V10 -> 8856197.1 | W11: =$B11*(1+W$3/12)^($B$1*12-$A11) -> 59068825 | X11: =W11+X10 -> 4.4581783e+08 | Y11: =W11/((1+'How much will I make'!$C$5/12)^(Calculations!$B$1*12-Calculations!$A11)) -> 8264460.8 | Z11: =Y11+Z10 -> 61579046 | AA11: =$B11*(1+AA$3/12)^($B$1*12-$A11) -> 4.0244966e+08 | AB11: =AA11+AB10 -> 3.0759864e+09 | AC11: =AA11/((1+'How much will I make'!$C$5/12)^(Calculations!$B$1*12-Calculations!$A11)) -> 56307696 | AD11: =AC11+AD10 -> 4.2484515e+08 | AE11: =$B11*(1+AE$3/12)^($B$1*12-$A11) -> 2.7208068e+09 | AF11: =AE11+AF10 -> 2.105962e+10 | AG11: =AE11/((1+'How much will I make'!$C$5/12)^(Calculations!$B$1*12-Calculations!$A11)) -> 3.806746e+08 | AH11: =AG11+AH10 -> 2.9084906e+09
A12: =A11+1 -> 8 | B12: =B11 -> 500 | C12: =$B12*(1+$C$3/12)^($B$1*12-$A12) -> 3558.8363 | D12: =C12+D11 -> 28889.366 | E12: =$C12/((1+'How much will I make'!$C$5/12)^(Calculations!$B$1*12-Calculations!$A12)) -> 500 | F12: =E12+F11 -> 4000 | G12: =$B12*(1+G$3/12)^($B$1*12-$A12) -> 25125.613 | H12: =G12+H11 -> 206966.28 | I12: =G12/((1+'How much will I make'!$C$5/12)^(Calculations!$B$1*12-Calculations!$A12)) -> 3530.0321 | J12: =I12+J11 -> 28653.806 | K12: =$B12*(1+K$3/12)^($B$1*12-$A12) -> 175964.5 | L12: =K12+L11 -> 1470867.5 | M12: =K12/((1+'How much will I make'!$C$5/12)^(Calculations!$B$1*12-Calculations!$A12)) -> 24722.196 | N12: =M12+N11 -> 203618.49 | O12: =$B12*(1+O$3/12)^($B$1*12-$A12) -> 1222536.8 | P12: =O12+P11 -> 10370231 | Q12: =O12/((1+'How much will I make'!$C$5/12)^(Calculations!$B$1*12-Calculations!$A12)) -> 171760.76 | R12: =Q12+R11 -> 1435466.7 | S12: =$B12*(1+S$3/12)^($B$1*12-$A12) -> 8426665.1 | T12: =S12+T11 -> 72539114 | U12: =S12/((1+'How much will I make'!$C$5/12)^(Calculations!$B$1*12-Calculations!$A12)) -> 1183907.4 | V12: =U12+V11 -> 10040105 | W12: =$B12*(1+W$3/12)^($B$1*12-$A12) -> 57628122 | X12: =W12+X11 -> 5.0344596e+08 | Y12: =W12/((1+'How much will I make'!$C$5/12)^(Calculations!$B$1*12-Calculations!$A12)) -> 8096484 | Z12: =Y12+Z11 -> 69675530 | AA12: =$B12*(1+AA$3/12)^($B$1*12-$A12) -> 3.9104421e+08 | AB12: =AA12+AB11 -> 3.4670306e+09 | AC12: =AA12/((1+'How much will I make'!$C$5/12)^(Calculations!$B$1*12-Calculations!$A12)) -> 54939898 | AD12: =AC12+AD11 -> 4.7978505e+08 | AE12: =$B12*(1+AE$3/12)^($B$1*12-$A12) -> 2.6330388e+09 | AF12: =AE12+AF11 -> 2.3692659e+10 | AG12: =AE12/((1+'How much will I make'!$C$5/12)^(Calculations!$B$1*12-Calculations!$A12)) -> 3.6992975e+08 | AH12: =AG12+AH11 -> 3.2784203e+09
A13: =A12+1 -> 9 | B13: =B12 -> 500 | C13: =$B13*(1+$C$3/12)^($B$1*12-$A13) -> 3544.0693 | D13: =C13+D12 -> 32433.435 | E13: =$C13/((1+'How much will I make'!$C$5/12)^(Calculations!$B$1*12-Calculations!$A13)) -> 500 | F13: =E13+F12 -> 4500 | G13: =$B13*(1+G$3/12)^($B$1*12-$A13) -> 24917.963 | H13: =G13+H12 -> 231884.24 | I13: =G13/((1+'How much will I make'!$C$5/12)^(Calculations!$B$1*12-Calculations!$A13)) -> 3515.4452 | J13: =I13+J12 -> 32169.251 | K13: =$B13*(1+K$3/12)^($B$1*12-$A13) -> 173792.1 | L13: =K13+L12 -> 1644659.6 | M13: =K13/((1+'How much will I make'!$C$5/12)^(Calculations!$B$1*12-Calculations!$A13)) -> 24518.721 | N13: =M13+N12 -> 228137.21 | O13: =$B13*(1+O$3/12)^($B$1*12-$A13) -> 1202495.2 | P13: =O13+P12 -> 11572726 | Q13: =O13/((1+'How much will I make'!$C$5/12)^(Calculations!$B$1*12-Calculations!$A13)) -> 169648.94 | R13: =Q13+R12 -> 1605115.7 | S13: =$B13*(1+S$3/12)^($B$1*12-$A13) -> 8254692.4 | T13: =S13+T12 -> 80793807 | U13: =S13/((1+'How much will I make'!$C$5/12)^(Calculations!$B$1*12-Calculations!$A13)) -> 1164578.3 | V13: =U13+V12 -> 11204683 | W13: =$B13*(1+W$3/12)^($B$1*12-$A13) -> 56222558 | X13: =W13+X12 -> 5.5966851e+08 | Y13: =W13/((1+'How much will I make'!$C$5/12)^(Calculations!$B$1*12-Calculations!$A13)) -> 7931921.3 | Z13: =Y13+Z12 -> 77607451 | AA13: =$B13*(1+AA$3/12)^($B$1*12-$A13) -> 3.7996198e+08 | AB13: =AA13+AB12 -> 3.8469926e+09 | AC13: =AA13/((1+'How much will I make'!$C$5/12)^(Calculations!$B$1*12-Calculations!$A13)) -> 53605325 | AD13: =AC13+AD12 -> 5.3339037e+08 | AE13: =$B13*(1+AE$3/12)^($B$1*12-$A13) -> 2.5481021e+09 | AF13: =AE13+AF12 -> 2.6240761e+10 | AG13: =AE13/((1+'How much will I make'!$C$5/12)^(Calculations!$B$1*12-Calculations!$A13)) -> 3.5948818e+08 | AH13: =AG13+AH12 -> 3.6379085e+09
A14: =A13+1 -> 10 | B14: =B13 -> 500 | C14: =$B14*(1+$C$3/12)^($B$1*12-$A14) -> 3529.3637 | D14: =C14+D13 -> 35962.799 | E14: =$C14/((1+'How much will I make'!$C$5/12)^(Calculations!$B$1*12-Calculations!$A14)) -> 500 | F14: =E14+F13 -> 5000 | G14: =$B14*(1+G$3/12)^($B$1*12-$A14) -> 24712.029 | H14: =G14+H13 -> 256596.27 | I14: =G14/((1+'How much will I make'!$C$5/12)^(Calculations!$B$1*12-Calculations!$A14)) -> 3500.9185 | J14: =I14+J13 -> 35670.17 | K14: =$B14*(1+K$3/12)^($B$1*12-$A14) -> 171646.52 | L14: =K14+L13 -> 1816306.2 | M14: =K14/((1+'How much will I make'!$C$5/12)^(Calculations!$B$1*12-Calculations!$A14)) -> 24316.921 | N14: =M14+N13 -> 252454.13 | O14: =$B14*(1+O$3/12)^($B$1*12-$A14) -> 1182782.2 | P14: =O14+P13 -> 12755508 | Q14: =O14/((1+'How much will I make'!$C$5/12)^(Calculations!$B$1*12-Calculations!$A14)) -> 167563.09 | R14: =Q14+R13 -> 1772678.8 | S14: =$B14*(1+S$3/12)^($B$1*12-$A14) -> 8086229.3 | T14: =S14+T13 -> 88880036 | U14: =S14/((1+'How much will I make'!$C$5/12)^(Calculations!$B$1*12-Calculations!$A14)) -> 1145564.8 | V14: =U14+V13 -> 12350248 | W14: =$B14*(1+W$3/12)^($B$1*12-$A14) -> 54851276 | X14: =W14+X13 -> 6.1451979e+08 | Y14: =W14/((1+'How much will I make'!$C$5/12)^(Calculations!$B$1*12-Calculations!$A14)) -> 7770703.4 | Z14: =Y14+Z13 -> 85378154 | AA14: =$B14*(1+AA$3/12)^($B$1*12-$A14) -> 3.6919383e+08 | AB14: =AA14+AB13 -> 4.2161864e+09 | AC14: =AA14/((1+'How much will I make'!$C$5/12)^(Calculations!$B$1*12-Calculations!$A14)) -> 52303172 | AD14: =AC14+AD13 -> 5.8569355e+08 | AE14: =$B14*(1+AE$3/12)^($B$1*12-$A14) -> 2.4659053e+09 | AF14: =AE14+AF13 -> 2.8706666e+10 | AG14: =AE14/((1+'How much will I make'!$C$5/12)^(Calculations!$B$1*12-Calculations!$A14)) -> 3.4934134e+08 | AH14: =AG14+AH13 -> 3.9872499e+09
A15: =A14+1 -> 11 | B15: =B14 -> 500 | C15: =$B15*(1+$C$3/12)^($B$1*12-$A15) -> 3514.719 | D15: =C15+D14 -> 39477.518 | E15: =$C15/((1+'How much will I make'!$C$5/12)^(Calculations!$B$1*12-Calculations!$A15)) -> 500 | F15: =E15+F14 -> 5500 | G15: =$B15*(1+G$3/12)^($B$1*12-$A15) -> 24507.798 | H15: =G15+H14 -> 281104.07 | I15: =G15/((1+'How much will I make'!$C$5/12)^(Calculations!$B$1*12-Calculations!$A15)) -> 3486.4519 | J15: =I15+J14 -> 39156.622 | K15: =$B15*(1+K$3/12)^($B$1*12-$A15) -> 169527.42 | L15: =K15+L14 -> 1985833.6 | M15: =K15/((1+'How much will I make'!$C$5/12)^(Calculations!$B$1*12-Calculations!$A15)) -> 24116.782 | N15: =M15+N14 -> 276570.91 | O15: =$B15*(1+O$3/12)^($B$1*12-$A15) -> 1163392.3 | P15: =O15+P14 -> 13918900 | Q15: =O15/((1+'How much will I make'!$C$5/12)^(Calculations!$B$1*12-Calculations!$A15)) -> 165502.89 | R15: =Q15+R14 -> 1938181.7 | S15: =$B15*(1+S$3/12)^($B$1*12-$A15) -> 7921204.2 | T15: =S15+T14 -> 96801240 | U15: =S15/((1+'How much will I make'!$C$5/12)^(Calculations!$B$1*12-Calculations!$A15)) -> 1126861.7 | V15: =U15+V14 -> 13477109 | W15: =$B15*(1+W$3/12)^($B$1*12-$A15) -> 53513440 | X15: =W15+X14 -> 6.6803323e+08 | Y15: =W15/((1+'How much will I make'!$C$5/12)^(Calculations!$B$1*12-Calculations!$A15)) -> 7612762.3 | Z15: =Y15+Z14 -> 92990917 | AA15: =$B15*(1+AA$3/12)^($B$1*12-$A15) -> 3.5873084e+08 | AB15: =AA15+AB14 -> 4.5749172e+09 | AC15: =AA15/((1+'How much will I make'!$C$5/12)^(Calculations!$B$1*12-Calculations!$A15)) -> 51032649 | AD15: =AC15+AD14 -> 6.367262e+08 | AE15: =$B15*(1+AE$3/12)^($B$1*12-$A15) -> 2.3863599e+09 | AF15: =AE15+AF14 -> 3.1093026e+10 | AG15: =AE15/((1+'How much will I make'!$C$5/12)^(Calculations!$B$1*12-Calculations!$A15)) -> 3.394809e+08 | AH15: =AG15+AH14 -> 4.3267308e+09
A16: =A15+1 -> 12 | B16: =B15 -> 500 | C16: =$B16*(1+$C$3/12)^($B$1*12-$A16) -> 3500.1351 | D16: =C16+D15 -> 42977.653 | E16: =$C16/((1+'How much will I make'!$C$5/12)^(Calculations!$B$1*12-Calculations!$A16)) -> 500 | F16: =E16+F15 -> 6000 | G16: =$B16*(1+G$3/12)^($B$1*12-$A16) -> 24305.254 | H16: =G16+H15 -> 305409.32 | I16: =G16/((1+'How much will I make'!$C$5/12)^(Calculations!$B$1*12-Calculations!$A16)) -> 3472.0451 | J16: =I16+J15 -> 42628.667 | K16: =$B16*(1+K$3/12)^($B$1*12-$A16) -> 167434.49 | L16: =K16+L15 -> 2153268.1 | M16: =K16/((1+'How much will I make'!$C$5/12)^(Calculations!$B$1*12-Calculations!$A16)) -> 23918.29 | N16: =M16+N15 -> 300489.2 | O16: =$B16*(1+O$3/12)^($B$1*12-$A16) -> 1144320.3 | P16: =O16+P15 -> 15063221 | Q16: =O16/((1+'How much will I make'!$C$5/12)^(Calculations!$B$1*12-Calculations!$A16)) -> 163468.02 | R16: =Q16+R15 -> 2101649.7 | S16: =$B16*(1+S$3/12)^($B$1*12-$A16) -> 7759547 | T16: =S16+T15 -> 1.0456079e+08 | U16: =S16/((1+'How much will I make'!$C$5/12)^(Calculations!$B$1*12-Calculations!$A16)) -> 1108463.9 | V16: =U16+V15 -> 14585573 | W16: =$B16*(1+W$3/12)^($B$1*12-$A16) -> 52208235 | X16: =W16+X15 -> 7.2024147e+08 | Y16: =W16/((1+'How much will I make'!$C$5/12)^(Calculations!$B$1*12-Calculations!$A16)) -> 7458031.3 | Z16: =Y16+Z15 -> 1.0044895e+08 | AA16: =$B16*(1+AA$3/12)^($B$1*12-$A16) -> 3.4856438e+08 | AB16: =AA16+AB15 -> 4.9234816e+09 | AC16: =AA16/((1+'How much will I make'!$C$5/12)^(Calculations!$B$1*12-Calculations!$A16)) -> 49792990 | AD16: =AC16+AD15 -> 6.8651919e+08 | AE16: =$B16*(1+AE$3/12)^($B$1*12-$A16) -> 2.3093806e+09 | AF16: =AE16+AF15 -> 3.3402407e+10 | AG16: =AE16/((1+'How much will I make'!$C$5/12)^(Calculations!$B$1*12-Calculations!$A16)) -> 3.2989878e+08 | AH16: =AG16+AH15 -> 4.6566295e+09
A17: =A16+1 -> 13 | B17: =B16*(1+'How much will I make'!$C$4) -> 525 | C17: =$B17*(1+$C$3/12)^($B$1*12-$A17) -> 3659.8923 | D17: =C17+D16 -> 46637.545 | E17: =$C17/((1+'How much will I make'!$C$5/12)^(Calculations!$B$1*12-Calculations!$A17)) -> 525 | F17: =E17+F16 -> 6525 | G17: =$B17*(1+G$3/12)^($B$1*12-$A17) -> 25309.603 | H17: =G17+H16 -> 330718.93 | I17: =G17/((1+'How much will I make'!$C$5/12)^(Calculations!$B$1*12-Calculations!$A17)) -> 3630.5827 | J17: =I17+J16 -> 46259.25 | K17: =$B17*(1+K$3/12)^($B$1*12-$A17) -> 173635.77 | L17: =K17+L16 -> 2326903.8 | M17: =K17/((1+'How much will I make'!$C$5/12)^(Calculations!$B$1*12-Calculations!$A17)) -> 24907.503 | N17: =M17+N16 -> 325396.7 | O17: =$B17*(1+O$3/12)^($B$1*12-$A17) -> 1181839 | P17: =O17+P16 -> 16245060 | Q17: =O17/((1+'How much will I make'!$C$5/12)^(Calculations!$B$1*12-Calculations!$A17)) -> 169531.08 | R17: =Q17+R16 -> 2271180.8 | S17: =$B17*(1+S$3/12)^($B$1*12-$A17) -> 7981248.3 | T17: =S17+T16 -> 1.1254204e+08 | U17: =S17/((1+'How much will I make'!$C$5/12)^(Calculations!$B$1*12-Calculations!$A17)) -> 1144884.9 | V17: =U17+V16 -> 15730458 | W17: =$B17*(1+W$3/12)^($B$1*12-$A17) -> 53481606 | X17: =W17+X16 -> 7.7372307e+08 | Y17: =W17/((1+'How much will I make'!$C$5/12)^(Calculations!$B$1*12-Calculations!$A17)) -> 7671767.6 | Z17: =Y17+Z16 -> 1.0812072e+08 | AA17: =$B17*(1+AA$3/12)^($B$1*12-$A17) -> 3.5562034e+08 | AB17: =AA17+AB16 -> 5.279102e+09 | AC17: =AA17/((1+'How much will I make'!$C$5/12)^(Calculations!$B$1*12-Calculations!$A17)) -> 51012616 | AD17: =AC17+AD16 -> 7.375318e+08 | AE17: =$B17*(1+AE$3/12)^($B$1*12-$A17) -> 2.3466287e+09 | AF17: =AE17+AF16 -> 3.5749035e+10 | AG17: =AE17/((1+'How much will I make'!$C$5/12)^(Calculations!$B$1*12-Calculations!$A17)) -> 3.3661647e+08 | AH17: =AG17+AH16 -> 4.993246e+09
A18: =A17+1 -> 14 | B18: =B17 -> 525 | C18: =$B18*(1+$C$3/12)^($B$1*12-$A18) -> 3644.706 | D18: =C18+D17 -> 50282.251 | E18: =$C18/((1+'How much will I make'!$C$5/12)^(Calculations!$B$1*12-Calculations!$A18)) -> 525 | F18: =E18+F17 -> 7050 | G18: =$B18*(1+G$3/12)^($B$1*12-$A18) -> 25100.433 | H18: =G18+H17 -> 355819.36 | I18: =G18/((1+'How much will I make'!$C$5/12)^(Calculations!$B$1*12-Calculations!$A18)) -> 3615.5803 | J18: =I18+J17 -> 49874.83 | K18: =$B18*(1+K$3/12)^($B$1*12-$A18) -> 171492.12 | L18: =K18+L17 -> 2498396 | M18: =K18/((1+'How much will I make'!$C$5/12)^(Calculations!$B$1*12-Calculations!$A18)) -> 24702.503 | N18: =M18+N17 -> 350099.21 | O18: =$B18*(1+O$3/12)^($B$1*12-$A18) -> 1162464.6 | P18: =O18+P17 -> 17407524 | Q18: =O18/((1+'How much will I make'!$C$5/12)^(Calculations!$B$1*12-Calculations!$A18)) -> 167446.68 | R18: =Q18+R17 -> 2438627.5 | S18: =$B18*(1+S$3/12)^($B$1*12-$A18) -> 7818365.7 | T18: =S18+T17 -> 1.203604e+08 | U18: =S18/((1+'How much will I make'!$C$5/12)^(Calculations!$B$1*12-Calculations!$A18)) -> 1126192.9 | V18: =U18+V17 -> 16856651 | W18: =$B18*(1+W$3/12)^($B$1*12-$A18) -> 52177177 | X18: =W18+X17 -> 8.2590025e+08 | Y18: =W18/((1+'How much will I make'!$C$5/12)^(Calculations!$B$1*12-Calculations!$A18)) -> 7515837.4 | Z18: =Y18+Z17 -> 1.1563655e+08 | AA18: =$B18*(1+AA$3/12)^($B$1*12-$A18) -> 3.4554203e+08 | AB18: =AA18+AB17 -> 5.624644e+09 | AC18: =AA18/((1+'How much will I make'!$C$5/12)^(Calculations!$B$1*12-Calculations!$A18)) -> 49773443 | AD18: =AC18+AD17 -> 7.8730524e+08 | AE18: =$B18*(1+AE$3/12)^($B$1*12-$A18) -> 2.270931e+09 | AF18: =AE18+AF17 -> 3.8019966e+10 | AG18: =AE18/((1+'How much will I make'!$C$5/12)^(Calculations!$B$1*12-Calculations!$A18)) -> 3.271152e+08 | AH18: =AG18+AH17 -> 5.3203612e+09
A19: =A18+1 -> 15 | B19: =B18 -> 525 | C19: =$B19*(1+$C$3/12)^($B$1*12-$A19) -> 3629.5828 | D19: =C19+D18 -> 53911.834 | E19: =$C19/((1+'How much will I make'!$C$5/12)^(Calculations!$B$1*12-Calculations!$A19)) -> 525 | F19: =E19+F18 -> 7575 | G19: =$B19*(1+G$3/12)^($B$1*12-$A19) -> 24892.991 | H19: =G19+H18 -> 380712.35 | I19: =G19/((1+'How much will I make'!$C$5/12)^(Calculations!$B$1*12-Calculations!$A19)) -> 3600.6399 | J19: =I19+J18 -> 53475.47 | K19: =$B19*(1+K$3/12)^($B$1*12-$A19) -> 169374.93 | L19: =K19+L18 -> 2667770.9 | M19: =K19/((1+'How much will I make'!$C$5/12)^(Calculations!$B$1*12-Calculations!$A19)) -> 24499.19 | N19: =M19+N18 -> 374598.4 | O19: =$B19*(1+O$3/12)^($B$1*12-$A19) -> 1143407.8 | P19: =O19+P18 -> 18550932 | Q19: =O19/((1+'How much will I make'!$C$5/12)^(Calculations!$B$1*12-Calculations!$A19)) -> 165387.91 | R19: =Q19+R18 -> 2604015.4 | S19: =$B19*(1+S$3/12)^($B$1*12-$A19) -> 7658807.2 | T19: =S19+T18 -> 1.2801921e+08 | U19: =S19/((1+'How much will I make'!$C$5/12)^(Calculations!$B$1*12-Calculations!$A19)) -> 1107806.1 | V19: =U19+V18 -> 17964457 | W19: =$B19*(1+W$3/12)^($B$1*12-$A19) -> 50904563 | X19: =W19+X18 -> 8.7680481e+08 | Y19: =W19/((1+'How much will I make'!$C$5/12)^(Calculations!$B$1*12-Calculations!$A19)) -> 7363076.4 | Z19: =Y19+Z18 -> 1.2299963e+08 | AA19: =$B19*(1+AA$3/12)^($B$1*12-$A19) -> 3.3574934e+08 | AB19: =AA19+AB18 -> 5.9603933e+09 | AC19: =AA19/((1+'How much will I make'!$C$5/12)^(Calculations!$B$1*12-Calculations!$A19)) -> 48564371 | AD19: =AC19+AD18 -> 8.3586962e+08 | AE19: =$B19*(1+AE$3/12)^($B$1*12-$A19) -> 2.1976751e+09 | AF19: =AE19+AF18 -> 4.0217641e+10 | AG19: =AE19/((1+'How much will I make'!$C$5/12)^(Calculations!$B$1*12-Calculations!$A19)) -> 3.1788211e+08 | AH19: =AG19+AH18 -> 5.6382433e+09
A20: =A19+1 -> 16 | B20: =B19 -> 525 | C20: =$B20*(1+$C$3/12)^($B$1*12-$A20) -> 3614.5223 | D20: =C20+D19 -> 57526.357 | E20: =$C20/((1+'How much will I make'!$C$5/12)^(Calculations!$B$1*12-Calculations!$A20)) -> 525 | F20: =E20+F19 -> 8100 | G20: =$B20*(1+G$3/12)^($B$1*12-$A20) -> 24687.264 | H20: =G20+H19 -> 405399.61 | I20: =G20/((1+'How much will I make'!$C$5/12)^(Calculations!$B$1*12-Calculations!$A20)) -> 3585.7612 | J20: =I20+J19 -> 57061.231 | K20: =$B20*(1+K$3/12)^($B$1*12-$A20) -> 167283.88 | L20: =K20+L19 -> 2835054.8 | M20: =K20/((1+'How much will I make'!$C$5/12)^(Calculations!$B$1*12-Calculations!$A20)) -> 24297.551 | N20: =M20+N19 -> 398895.95 | O20: =$B20*(1+O$3/12)^($B$1*12-$A20) -> 1124663.4 | P20: =O20+P19 -> 19675595 | Q20: =O20/((1+'How much will I make'!$C$5/12)^(Calculations!$B$1*12-Calculations!$A20)) -> 163354.45 | R20: =Q20+R19 -> 2767369.8 | S20: =$B20*(1+S$3/12)^($B$1*12-$A20) -> 7502505 | T20: =S20+T19 -> 1.3552171e+08 | U20: =S20/((1+'How much will I make'!$C$5/12)^(Calculations!$B$1*12-Calculations!$A20)) -> 1089719.4 | V20: =U20+V19 -> 19054176 | W20: =$B20*(1+W$3/12)^($B$1*12-$A20) -> 49662988 | X20: =W20+X19 -> 9.264678e+08 | Y20: =W20/((1+'How much will I make'!$C$5/12)^(Calculations!$B$1*12-Calculations!$A20)) -> 7213420.4 | Z20: =Y20+Z19 -> 1.3021305e+08 | AA20: =$B20*(1+AA$3/12)^($B$1*12-$A20) -> 3.2623418e+08 | AB20: =AA20+AB19 -> 6.2866275e+09 | AC20: =AA20/((1+'How much will I make'!$C$5/12)^(Calculations!$B$1*12-Calculations!$A20)) -> 47384670 | AD20: =AC20+AD19 -> 8.8325429e+08 | AE20: =$B20*(1+AE$3/12)^($B$1*12-$A20) -> 2.1267824e+09 | AF20: =AE20+AF19 -> 4.2344424e+10 | AG20: =AE20/((1+'How much will I make'!$C$5/12)^(Calculations!$B$1*12-Calculations!$A20)) -> 3.0890963e+08 | AH20: =AG20+AH19 -> 5.947153e+09
A21: =A20+1 -> 17 | B21: =B20 -> 525 | C21: =$B21*(1+$C$3/12)^($B$1*12-$A21) -> 3599.5242 | D21: =C21+D20 -> 61125.881 | E21: =$C21/((1+'How much will I make'!$C$5/12)^(Calculations!$B$1*12-Calculations!$A21)) -> 525 | F21: =E21+F20 -> 8625 | G21: =$B21*(1+G$3/12)^($B$1*12-$A21) -> 24483.237 | H21: =G21+H20 -> 429882.85 | I21: =G21/((1+'How much will I make'!$C$5/12)^(Calculations!$B$1*12-Calculations!$A21)) -> 3570.944 | J21: =I21+J20 -> 60632.175 | K21: =$B21*(1+K$3/12)^($B$1*12-$A21) -> 165218.65 | L21: =K21+L20 -> 3000273.4 | M21: =K21/((1+'How much will I make'!$C$5/12)^(Calculations!$B$1*12-Calculations!$A21)) -> 24097.571 | N21: =M21+N20 -> 422993.52 | O21: =$B21*(1+O$3/12)^($B$1*12-$A21) -> 1106226.3 | P21: =O21+P20 -> 20781822 | Q21: =O21/((1+'How much will I make'!$C$5/12)^(Calculations!$B$1*12-Calculations!$A21)) -> 161345.99 | R21: =Q21+R20 -> 2928715.8 | S21: =$B21*(1+S$3/12)^($B$1*12-$A21) -> 7349392.7 | T21: =S21+T20 -> 1.4287111e+08 | U21: =S21/((1+'How much will I make'!$C$5/12)^(Calculations!$B$1*12-Calculations!$A21)) -> 1071928.1 | V21: =U21+V20 -> 20126104 | W21: =$B21*(1+W$3/12)^($B$1*12-$A21) -> 48451696 | X21: =W21+X20 -> 9.7491949e+08 | Y21: =W21/((1+'How much will I make'!$C$5/12)^(Calculations!$B$1*12-Calculations!$A21)) -> 7066806.2 | Z21: =Y21+Z20 -> 1.3727986e+08 | AA21: =$B21*(1+AA$3/12)^($B$1*12-$A21) -> 3.1698868e+08 | AB21: =AA21+AB20 -> 6.6036162e+09 | AC21: =AA21/((1+'How much will I make'!$C$5/12)^(Calculations!$B$1*12-Calculations!$A21)) -> 46233625 | AD21: =AC21+AD20 -> 9.2948791e+08 | AE21: =$B21*(1+AE$3/12)^($B$1*12-$A21) -> 2.0581765e+09 | AF21: =AE21+AF20 -> 4.44026e+10 | AG21: =AE21/((1+'How much will I make'!$C$5/12)^(Calculations!$B$1*12-Calculations!$A21)) -> 3.0019041e+08 | AH21: =AG21+AH20 -> 6.2473434e+09
A22: =A21+1 -> 18 | B22: =B21 -> 525 | C22: =$B22*(1+$C$3/12)^($B$1*12-$A22) -> 3584.5885 | D22: =C22+D21 -> 64710.469 | E22: =$C22/((1+'How much will I make'!$C$5/12)^(Calculations!$B$1*12-Calculations!$A22)) -> 525 | F22: =E22+F21 -> 9150 | G22: =$B22*(1+G$3/12)^($B$1*12-$A22) -> 24280.896 | H22: =G22+H21 -> 454163.75 | I22: =G22/((1+'How much will I make'!$C$5/12)^(Calculations!$B$1*12-Calculations!$A22)) -> 3556.188 | J22: =I22+J21 -> 64188.363 | K22: =$B22*(1+K$3/12)^($B$1*12-$A22) -> 163178.91 | L22: =K22+L21 -> 3163452.3 | M22: =K22/((1+'How much will I make'!$C$5/12)^(Calculations!$B$1*12-Calculations!$A22)) -> 23899.237 | N22: =M22+N21 -> 446892.76 | O22: =$B22*(1+O$3/12)^($B$1*12-$A22) -> 1088091.5 | P22: =O22+P21 -> 21869913 | Q22: =O22/((1+'How much will I make'!$C$5/12)^(Calculations!$B$1*12-Calculations!$A22)) -> 159362.23 | R22: =Q22+R21 -> 3088078 | S22: =$B22*(1+S$3/12)^($B$1*12-$A22) -> 7199405.1 | T22: =S22+T21 -> 1.5007051e+08 | U22: =S22/((1+'How much will I make'!$C$5/12)^(Calculations!$B$1*12-Calculations!$A22)) -> 1054427.2 | V22: =U22+V21 -> 21180532 | W22: =$B22*(1+W$3/12)^($B$1*12-$A22) -> 47269947 | X22: =W22+X21 -> 1.0221894e+09 | Y22: =W22/((1+'How much will I make'!$C$5/12)^(Calculations!$B$1*12-Calculations!$A22)) -> 6923171.9 | Z22: =Y22+Z21 -> 1.4420303e+08 | AA22: =$B22*(1+AA$3/12)^($B$1*12-$A22) -> 3.0800519e+08 | AB22: =AA22+AB21 -> 6.9116214e+09 | AC22: =AA22/((1+'How much will I make'!$C$5/12)^(Calculations!$B$1*12-Calculations!$A22)) -> 45110541 | AD22: =AC22+AD21 -> 9.7459845e+08 | AE22: =$B22*(1+AE$3/12)^($B$1*12-$A22) -> 1.9917837e+09 | AF22: =AE22+AF21 -> 4.6394384e+10 | AG22: =AE22/((1+'How much will I make'!$C$5/12)^(Calculations!$B$1*12-Calculations!$A22)) -> 2.9171729e+08 | AH22: =AG22+AH21 -> 6.5390607e+09
A23: =A22+1 -> 19 | B23: =B22 -> 525 | C23: =$B23*(1+$C$3/12)^($B$1*12-$A23) -> 3569.7146 | D23: =C23+D22 -> 68280.184 | E23: =$C23/((1+'How much will I make'!$C$5/12)^(Calculations!$B$1*12-Calculations!$A23)) -> 525 | F23: =E23+F22 -> 9675 | G23: =$B23*(1+G$3/12)^($B$1*12-$A23) -> 24080.228 | H23: =G23+H22 -> 478243.98 | I23: =G23/((1+'How much will I make'!$C$5/12)^(Calculations!$B$1*12-Calculations!$A23)) -> 3541.493 | J23: =I23+J22 -> 67729.856 | K23: =$B23*(1+K$3/12)^($B$1*12-$A23) -> 161164.36 | L23: =K23+L22 -> 3324616.7 | M23: =K23/((1+'How much will I make'!$C$5/12)^(Calculations!$B$1*12-Calculations!$A23)) -> 23702.535 | N23: =M23+N22 -> 470595.29 | O23: =$B23*(1+O$3/12)^($B$1*12-$A23) -> 1070253.9 | P23: =O23+P22 -> 22940167 | Q23: =O23/((1+'How much will I make'!$C$5/12)^(Calculations!$B$1*12-Calculations!$A23)) -> 157402.86 | R23: =Q23+R22 -> 3245480.9 | S23: =$B23*(1+S$3/12)^($B$1*12-$A23) -> 7052478.4 | T23: =S23+T22 -> 1.5712299e+08 | U23: =S23/((1+'How much will I make'!$C$5/12)^(Calculations!$B$1*12-Calculations!$A23)) -> 1037212.1 | V23: =U23+V22 -> 22217744 | W23: =$B23*(1+W$3/12)^($B$1*12-$A23) -> 46117021 | X23: =W23+X22 -> 1.0683065e+09 | Y23: =W23/((1+'How much will I make'!$C$5/12)^(Calculations!$B$1*12-Calculations!$A23)) -> 6782457 | Z23: =Y23+Z22 -> 1.5098548e+08 | AA23: =$B23*(1+AA$3/12)^($B$1*12-$A23) -> 2.992763e+08 | AB23: =AA23+AB22 -> 7.2108977e+09 | AC23: =AA23/((1+'How much will I make'!$C$5/12)^(Calculations!$B$1*12-Calculations!$A23)) -> 44014739 | AD23: =AC23+AD22 -> 1.0186132e+09 | AE23: =$B23*(1+AE$3/12)^($B$1*12-$A23) -> 1.9275326e+09 | AF23: =AE23+AF22 -> 4.8321917e+10 | AG23: =AE23/((1+'How much will I make'!$C$5/12)^(Calculations!$B$1*12-Calculations!$A23)) -> 2.8348334e+08 | AH23: =AG23+AH22 -> 6.822544e+09
A24: =A23+1 -> 20 | B24: =B23 -> 525 | C24: =$B24*(1+$C$3/12)^($B$1*12-$A24) -> 3554.9026 | D24: =C24+D23 -> 71835.086 | E24: =$C24/((1+'How much will I make'!$C$5/12)^(Calculations!$B$1*12-Calculations!$A24)) -> 525 | F24: =E24+F23 -> 10200 | G24: =$B24*(1+G$3/12)^($B$1*12-$A24) -> 23881.218 | H24: =G24+H23 -> 502125.19 | I24: =G24/((1+'How much will I make'!$C$5/12)^(Calculations!$B$1*12-Calculations!$A24)) -> 3526.8588 | J24: =I24+J23 -> 71256.715 | K24: =$B24*(1+K$3/12)^($B$1*12-$A24) -> 159174.67 | L24: =K24+L23 -> 3483791.4 | M24: =K24/((1+'How much will I make'!$C$5/12)^(Calculations!$B$1*12-Calculations!$A24)) -> 23507.453 | N24: =M24+N23 -> 494102.74 | O24: =$B24*(1+O$3/12)^($B$1*12-$A24) -> 1052708.7 | P24: =O24+P23 -> 23992876 | Q24: =O24/((1+'How much will I make'!$C$5/12)^(Calculations!$B$1*12-Calculations!$A24)) -> 155467.58 | R24: =Q24+R23 -> 3400948.5 | S24: =$B24*(1+S$3/12)^($B$1*12-$A24) -> 6908550.3 | T24: =S24+T23 -> 1.6403154e+08 | U24: =S24/((1+'How much will I make'!$C$5/12)^(Calculations!$B$1*12-Calculations!$A24)) -> 1020278 | V24: =U24+V23 -> 23238022 | W24: =$B24*(1+W$3/12)^($B$1*12-$A24) -> 44992216 | X24: =W24+X23 -> 1.1132987e+09 | Y24: =W24/((1+'How much will I make'!$C$5/12)^(Calculations!$B$1*12-Calculations!$A24)) -> 6644602.2 | Z24: =Y24+Z23 -> 1.5763009e+08 | AA24: =$B24*(1+AA$3/12)^($B$1*12-$A24) -> 2.9079479e+08 | AB24: =AA24+AB23 -> 7.5016925e+09 | AC24: =AA24/((1+'How much will I make'!$C$5/12)^(Calculations!$B$1*12-Calculations!$A24)) -> 42945555 | AD24: =AC24+AD23 -> 1.0615587e+09 | AE24: =$B24*(1+AE$3/12)^($B$1*12-$A24) -> 1.8653541e+09 | AF24: =AE24+AF23 -> 5.0187271e+10 | AG24: =AE24/((1+'How much will I make'!$C$5/12)^(Calculations!$B$1*12-Calculations!$A24)) -> 2.7548179e+08 | AH24: =AG24+AH23 -> 7.0980258e+09
A25: =A24+1 -> 21 | B25: =B24 -> 525 | C25: =$B25*(1+$C$3/12)^($B$1*12-$A25) -> 3540.1519 | D25: =C25+D24 -> 75375.238 | E25: =$C25/((1+'How much will I make'!$C$5/12)^(Calculations!$B$1*12-Calculations!$A25)) -> 525 | F25: =E25+F24 -> 10725 | G25: =$B25*(1+G$3/12)^($B$1*12-$A25) -> 23683.852 | H25: =G25+H24 -> 525809.05 | I25: =G25/((1+'How much will I make'!$C$5/12)^(Calculations!$B$1*12-Calculations!$A25)) -> 3512.285 | J25: =I25+J24 -> 74769 | K25: =$B25*(1+K$3/12)^($B$1*12-$A25) -> 157209.56 | L25: =K25+L24 -> 3641000.9 | M25: =K25/((1+'How much will I make'!$C$5/12)^(Calculations!$B$1*12-Calculations!$A25)) -> 23313.976 | N25: =M25+N24 -> 517416.72 | O25: =$B25*(1+O$3/12)^($B$1*12-$A25) -> 1035451.2 | P25: =O25+P24 -> 25028327 | Q25: =O25/((1+'How much will I make'!$C$5/12)^(Calculations!$B$1*12-Calculations!$A25)) -> 153556.09 | R25: =Q25+R24 -> 3554504.6 | S25: =$B25*(1+S$3/12)^($B$1*12-$A25) -> 6767559.5 | T25: =S25+T24 -> 1.707991e+08 | U25: =S25/((1+'How much will I make'!$C$5/12)^(Calculations!$B$1*12-Calculations!$A25)) -> 1003620.4 | V25: =U25+V24 -> 24241642 | W25: =$B25*(1+W$3/12)^($B$1*12-$A25) -> 43894845 | X25: =W25+X24 -> 1.1571935e+09 | Y25: =W25/((1+'How much will I make'!$C$5/12)^(Calculations!$B$1*12-Calculations!$A25)) -> 6509549.3 | Z25: =Y25+Z24 -> 1.6413964e+08 | AA25: =$B25*(1+AA$3/12)^($B$1*12-$A25) -> 2.8255364e+08 | AB25: =AA25+AB24 -> 7.7842461e+09 | AC25: =AA25/((1+'How much will I make'!$C$5/12)^(Calculations!$B$1*12-Calculations!$A25)) -> 41902343 | AD25: =AC25+AD24 -> 1.1034611e+09 | AE25: =$B25*(1+AE$3/12)^($B$1*12-$A25) -> 1.8051814e+09 | AF25: =AE25+AF24 -> 5.1992452e+10 | AG25: =AE25/((1+'How much will I make'!$C$5/12)^(Calculations!$B$1*12-Calculations!$A25)) -> 2.677061e+08 | AH25: =AG25+AH24 -> 7.3657319e+09
A26: =A25+1 -> 22 | B26: =B25 -> 525 | C26: =$B26*(1+$C$3/12)^($B$1*12-$A26) -> 3525.4625 | D26: =C26+D25 -> 78900.701 | E26: =$C26/((1+'How much will I make'!$C$5/12)^(Calculations!$B$1*12-Calculations!$A26)) -> 525 | F26: =E26+F25 -> 11250 | G26: =$B26*(1+G$3/12)^($B$1*12-$A26) -> 23488.118 | H26: =G26+H25 -> 549297.16 | I26: =G26/((1+'How much will I make'!$C$5/12)^(Calculations!$B$1*12-Calculations!$A26)) -> 3497.7714 | J26: =I26+J25 -> 78266.771 | K26: =$B26*(1+K$3/12)^($B$1*12-$A26) -> 155268.7 | L26: =K26+L25 -> 3796269.6 | M26: =K26/((1+'How much will I make'!$C$5/12)^(Calculations!$B$1*12-Calculations!$A26)) -> 23122.091 | N26: =M26+N25 -> 540538.81 | O26: =$B26*(1+O$3/12)^($B$1*12-$A26) -> 1018476.6 | P26: =O26+P25 -> 26046804 | Q26: =O26/((1+'How much will I make'!$C$5/12)^(Calculations!$B$1*12-Calculations!$A26)) -> 151668.11 | R26: =Q26+R25 -> 3706172.7 | S26: =$B26*(1+S$3/12)^($B$1*12-$A26) -> 6629446 | T26: =S26+T25 -> 1.7742855e+08 | U26: =S26/((1+'How much will I make'!$C$5/12)^(Calculations!$B$1*12-Calculations!$A26)) -> 987234.77 | V26: =U26+V25 -> 25228877 | W26: =$B26*(1+W$3/12)^($B$1*12-$A26) -> 42824239 | X26: =W26+X25 -> 1.2000178e+09 | Y26: =W26/((1+'How much will I make'!$C$5/12)^(Calculations!$B$1*12-Calculations!$A26)) -> 6377241.4 | Z26: =Y26+Z25 -> 1.7051688e+08 | AA26: =$B26*(1+AA$3/12)^($B$1*12-$A26) -> 2.7454605e+08 | AB26: =AA26+AB25 -> 8.0587922e+09 | AC26: =AA26/((1+'How much will I make'!$C$5/12)^(Calculations!$B$1*12-Calculations!$A26)) -> 40884472 | AD26: =AC26+AD25 -> 1.1443456e+09 | AE26: =$B26*(1+AE$3/12)^($B$1*12-$A26) -> 1.7469498e+09 | AF26: =AE26+AF25 -> 5.3739402e+10 | AG26: =AE26/((1+'How much will I make'!$C$5/12)^(Calculations!$B$1*12-Calculations!$A26)) -> 2.6014988e+08 | AH26: =AG26+AH25 -> 7.6258818e+09
A27: =A26+1 -> 23 | B27: =B26 -> 525 | C27: =$B27*(1+$C$3/12)^($B$1*12-$A27) -> 3510.834 | D27: =C27+D26 -> 82411.535 | E27: =$C27/((1+'How much will I make'!$C$5/12)^(Calculations!$B$1*12-Calculations!$A27)) -> 525 | F27: =E27+F26 -> 11775 | G27: =$B27*(1+G$3/12)^($B$1*12-$A27) -> 23294.001 | H27: =G27+H26 -> 572591.17 | I27: =G27/((1+'How much will I make'!$C$5/12)^(Calculations!$B$1*12-Calculations!$A27)) -> 3483.3178 | J27: =I27+J26 -> 81750.089 | K27: =$B27*(1+K$3/12)^($B$1*12-$A27) -> 153351.8 | L27: =K27+L26 -> 3949621.4 | M27: =K27/((1+'How much will I make'!$C$5/12)^(Calculations!$B$1*12-Calculations!$A27)) -> 22931.786 | N27: =M27+N26 -> 563470.6 | O27: =$B27*(1+O$3/12)^($B$1*12-$A27) -> 1001780.3 | P27: =O27+P26 -> 27048584 | Q27: =O27/((1+'How much will I make'!$C$5/12)^(Calculations!$B$1*12-Calculations!$A27)) -> 149803.34 | R27: =Q27+R26 -> 3855976 | S27: =$B27*(1+S$3/12)^($B$1*12-$A27) -> 6494151.2 | T27: =S27+T26 -> 1.839227e+08 | U27: =S27/((1+'How much will I make'!$C$5/12)^(Calculations!$B$1*12-Calculations!$A27)) -> 971116.65 | V27: =U27+V26 -> 26199994 | W27: =$B27*(1+W$3/12)^($B$1*12-$A27) -> 41779745 | X27: =W27+X26 -> 1.2417975e+09 | Y27: =W27/((1+'How much will I make'!$C$5/12)^(Calculations!$B$1*12-Calculations!$A27)) -> 6247622.7 | Z27: =Y27+Z26 -> 1.767645e+08 | AA27: =$B27*(1+AA$3/12)^($B$1*12-$A27) -> 2.6676539e+08 | AB27: =AA27+AB26 -> 8.3255576e+09 | AC27: =AA27/((1+'How much will I make'!$C$5/12)^(Calculations!$B$1*12-Calculations!$A27)) -> 39891327 | AD27: =AC27+AD26 -> 1.1842369e+09 | AE27: =$B27*(1+AE$3/12)^($B$1*12-$A27) -> 1.6905966e+09 | AF27: =AE27+AF26 -> 5.5429998e+10 | AG27: =AE27/((1+'How much will I make'!$C$5/12)^(Calculations!$B$1*12-Calculations!$A27)) -> 2.5280694e+08 | AH27: =AG27+AH26 -> 7.8786887e+09
A28: =A27+1 -> 24 | B28: =B27 -> 525 | C28: =$B28*(1+$C$3/12)^($B$1*12-$A28) -> 3496.2662 | D28: =C28+D27 -> 85907.801 | E28: =$C28/((1+'How much will I make'!$C$5/12)^(Calculations!$B$1*12-Calculations!$A28)) -> 525 | F28: =E28+F27 -> 12300 | G28: =$B28*(1+G$3/12)^($B$1*12-$A28) -> 23101.489 | H28: =G28+H27 -> 595692.65 | I28: =G28/((1+'How much will I make'!$C$5/12)^(Calculations!$B$1*12-Calculations!$A28)) -> 3468.9239 | J28: =I28+J27 -> 85219.013 | K28: =$B28*(1+K$3/12)^($B$1*12-$A28) -> 151458.57 | L28: =K28+L27 -> 4101080 | M28: =K28/((1+'How much will I make'!$C$5/12)^(Calculations!$B$1*12-Calculations!$A28)) -> 22743.047 | N28: =M28+N27 -> 586213.64 | O28: =$B28*(1+O$3/12)^($B$1*12-$A28) -> 985357.65 | P28: =O28+P27 -> 28033942 | Q28: =O28/((1+'How much will I make'!$C$5/12)^(Calculations!$B$1*12-Calculations!$A28)) -> 147961.49 | R28: =Q28+R27 -> 4003937.5 | S28: =$B28*(1+S$3/12)^($B$1*12-$A28) -> 6361617.5 | T28: =S28+T27 -> 1.9028431e+08 | U28: =S28/((1+'How much will I make'!$C$5/12)^(Calculations!$B$1*12-Calculations!$A28)) -> 955261.69 | V28: =U28+V27 -> 27155255 | W28: =$B28*(1+W$3/12)^($B$1*12-$A28) -> 40760727 | X28: =W28+X27 -> 1.2825582e+09 | Y28: =W28/((1+'How much will I make'!$C$5/12)^(Calculations!$B$1*12-Calculations!$A28)) -> 6120638.5 | Z28: =Y28+Z27 -> 1.8288514e+08 | AA28: =$B28*(1+AA$3/12)^($B$1*12-$A28) -> 2.5920524e+08 | AB28: =AA28+AB27 -> 8.5847628e+09 | AC28: =AA28/((1+'How much will I make'!$C$5/12)^(Calculations!$B$1*12-Calculations!$A28)) -> 38922307 | AD28: =AC28+AD27 -> 1.2231592e+09 | AE28: =$B28*(1+AE$3/12)^($B$1*12-$A28) -> 1.6360612e+09 | AF28: =AE28+AF27 -> 5.706606e+10 | AG28: =AE28/((1+'How much will I make'!$C$5/12)^(Calculations!$B$1*12-Calculations!$A28)) -> 2.4567126e+08 | AH28: =AG28+AH27 -> 8.1243599e+09
A29: =A28+1 -> 25 | B29: =B28*(1+'How much will I make'!$C$4) -> 551.25 | C29: =$B29*(1+$C$3/12)^($B$1*12-$A29) -> 3655.8469 | D29: =C29+D28 -> 89563.648 | E29: =$C29/((1+'How much will I make'!$C$5/12)^(Calculations!$B$1*12-Calculations!$A29)) -> 551.25 | F29: =E29+F28 -> 12851.25 | G29: =$B29*(1+G$3/12)^($B$1*12-$A29) -> 24056.096 | H29: =G29+H28 -> 619748.75 | I29: =G29/((1+'How much will I make'!$C$5/12)^(Calculations!$B$1*12-Calculations!$A29)) -> 3627.319 | J29: =I29+J28 -> 88846.332 | K29: =$B29*(1+K$3/12)^($B$1*12-$A29) -> 157068.14 | L29: =K29+L28 -> 4258148.1 | M29: =K29/((1+'How much will I make'!$C$5/12)^(Calculations!$B$1*12-Calculations!$A29)) -> 23683.655 | N29: =M29+N28 -> 609897.3 | O29: =$B29*(1+O$3/12)^($B$1*12-$A29) -> 1017664.5 | P29: =O29+P28 -> 29051606 | Q29: =O29/((1+'How much will I make'!$C$5/12)^(Calculations!$B$1*12-Calculations!$A29)) -> 153449.41 | R29: =Q29+R28 -> 4157386.9 | S29: =$B29*(1+S$3/12)^($B$1*12-$A29) -> 6543378 | T29: =S29+T28 -> 1.9682769e+08 | U29: =S29/((1+'How much will I make'!$C$5/12)^(Calculations!$B$1*12-Calculations!$A29)) -> 986648.86 | V29: =U29+V28 -> 28141904 | W29: =$B29*(1+W$3/12)^($B$1*12-$A29) -> 41754891 | X29: =W29+X28 -> 1.3243131e+09 | Y29: =W29/((1+'How much will I make'!$C$5/12)^(Calculations!$B$1*12-Calculations!$A29)) -> 6296047 | Z29: =Y29+Z28 -> 1.8918119e+08 | AA29: =$B29*(1+AA$3/12)^($B$1*12-$A29) -> 2.6445231e+08 | AB29: =AA29+AB28 -> 8.8492151e+09 | AC29: =AA29/((1+'How much will I make'!$C$5/12)^(Calculations!$B$1*12-Calculations!$A29)) -> 39875667 | AD29: =AC29+AD28 -> 1.2630349e+09 | AE29: =$B29*(1+AE$3/12)^($B$1*12-$A29) -> 1.6624493e+09 | AF29: =AE29+AF28 -> 5.8728509e+10 | AG29: =AE29/((1+'How much will I make'!$C$5/12)^(Calculations!$B$1*12-Calculations!$A29)) -> 2.5067384e+08 | AH29: =AG29+AH28 -> 8.3750338e+09
A30: =A29+1 -> 26 | B30: =B29 -> 551.25 | C30: =$B30*(1+$C$3/12)^($B$1*12-$A30) -> 3640.6774 | D30: =C30+D29 -> 93204.325 | E30: =$C30/((1+'How much will I make'!$C$5/12)^(Calculations!$B$1*12-Calculations!$A30)) -> 551.25 | F30: =E30+F29 -> 13402.5 | G30: =$B30*(1+G$3/12)^($B$1*12-$A30) -> 23857.285 | H30: =G30+H29 -> 643606.03 | I30: =G30/((1+'How much will I make'!$C$5/12)^(Calculations!$B$1*12-Calculations!$A30)) -> 3612.3301 | J30: =I30+J29 -> 92458.662 | K30: =$B30*(1+K$3/12)^($B$1*12-$A30) -> 155129.03 | L30: =K30+L29 -> 4413277.2 | M30: =K30/((1+'How much will I make'!$C$5/12)^(Calculations!$B$1*12-Calculations!$A30)) -> 23488.727 | N30: =M30+N29 -> 633386.03 | O30: =$B30*(1+O$3/12)^($B$1*12-$A30) -> 1000981.4 | P30: =O30+P29 -> 30052588 | Q30: =O30/((1+'How much will I make'!$C$5/12)^(Calculations!$B$1*12-Calculations!$A30)) -> 151562.73 | R30: =Q30+R29 -> 4308949.6 | S30: =$B30*(1+S$3/12)^($B$1*12-$A30) -> 6409839.7 | T30: =S30+T29 -> 2.0323753e+08 | U30: =S30/((1+'How much will I make'!$C$5/12)^(Calculations!$B$1*12-Calculations!$A30)) -> 970540.3 | V30: =U30+V29 -> 29112444 | W30: =$B30*(1+W$3/12)^($B$1*12-$A30) -> 40736479 | X30: =W30+X29 -> 1.3650496e+09 | Y30: =W30/((1+'How much will I make'!$C$5/12)^(Calculations!$B$1*12-Calculations!$A30)) -> 6168078.6 | Z30: =Y30+Z29 -> 1.9534926e+08 | AA30: =$B30*(1+AA$3/12)^($B$1*12-$A30) -> 2.5695771e+08 | AB30: =AA30+AB29 -> 9.1061728e+09 | AC30: =AA30/((1+'How much will I make'!$C$5/12)^(Calculations!$B$1*12-Calculations!$A30)) -> 38907028 | AD30: =AC30+AD29 -> 1.3019419e+09 | AE30: =$B30*(1+AE$3/12)^($B$1*12-$A30) -> 1.6088219e+09 | AF30: =AE30+AF29 -> 6.0337331e+10 | AG30: =AE30/((1+'How much will I make'!$C$5/12)^(Calculations!$B$1*12-Calculations!$A30)) -> 2.4359836e+08 | AH30: =AG30+AH29 -> 8.6186321e+09
A31: =A30+1 -> 27 | B31: =B30 -> 551.25 | C31: =$B31*(1+$C$3/12)^($B$1*12-$A31) -> 3625.5708 | D31: =C31+D30 -> 96829.896 | E31: =$C31/((1+'How much will I make'!$C$5/12)^(Calculations!$B$1*12-Calculations!$A31)) -> 551.25 | F31: =E31+F30 -> 13953.75 | G31: =$B31*(1+G$3/12)^($B$1*12-$A31) -> 23660.117 | H31: =G31+H30 -> 667266.15 | I31: =G31/((1+'How much will I make'!$C$5/12)^(Calculations!$B$1*12-Calculations!$A31)) -> 3597.4031 | J31: =I31+J30 -> 96056.065 | K31: =$B31*(1+K$3/12)^($B$1*12-$A31) -> 153213.86 | L31: =K31+L30 -> 4566491 | M31: =K31/((1+'How much will I make'!$C$5/12)^(Calculations!$B$1*12-Calculations!$A31)) -> 23295.405 | N31: =M31+N30 -> 656681.43 | O31: =$B31*(1+O$3/12)^($B$1*12-$A31) -> 984571.9 | P31: =O31+P30 -> 31037159 | Q31: =O31/((1+'How much will I make'!$C$5/12)^(Calculations!$B$1*12-Calculations!$A31)) -> 149699.26 | R31: =Q31+R30 -> 4458648.9 | S31: =$B31*(1+S$3/12)^($B$1*12-$A31) -> 6279026.6 | T31: =S31+T30 -> 2.0951656e+08 | U31: =S31/((1+'How much will I make'!$C$5/12)^(Calculations!$B$1*12-Calculations!$A31)) -> 954694.75 | V31: =U31+V30 -> 30067139 | W31: =$B31*(1+W$3/12)^($B$1*12-$A31) -> 39742906 | X31: =W31+X30 -> 1.4047925e+09 | Y31: =W31/((1+'How much will I make'!$C$5/12)^(Calculations!$B$1*12-Calculations!$A31)) -> 6042711.1 | Z31: =Y31+Z30 -> 2.0139198e+08 | AA31: =$B31*(1+AA$3/12)^($B$1*12-$A31) -> 2.496755e+08 | AB31: =AA31+AB30 -> 9.3558483e+09 | AC31: =AA31/((1+'How much will I make'!$C$5/12)^(Calculations!$B$1*12-Calculations!$A31)) -> 37961918 | AD31: =AC31+AD30 -> 1.3399038e+09 | AE31: =$B31*(1+AE$3/12)^($B$1*12-$A31) -> 1.5569244e+09 | AF31: =AE31+AF30 -> 6.1894255e+10 | AG31: =AE31/((1+'How much will I make'!$C$5/12)^(Calculations!$B$1*12-Calculations!$A31)) -> 2.367226e+08 | AH31: =AG31+AH30 -> 8.8553548e+09
A32: =A31+1 -> 28 | B32: =B31 -> 551.25 | C32: =$B32*(1+$C$3/12)^($B$1*12-$A32) -> 3610.527 | D32: =C32+D31 -> 100440.42 | E32: =$C32/((1+'How much will I make'!$C$5/12)^(Calculations!$B$1*12-Calculations!$A32)) -> 551.25 | F32: =E32+F31 -> 14505 | G32: =$B32*(1+G$3/12)^($B$1*12-$A32) -> 23464.579 | H32: =G32+H31 -> 690730.73 | I32: =G32/((1+'How much will I make'!$C$5/12)^(Calculations!$B$1*12-Calculations!$A32)) -> 3582.5378 | J32: =I32+J31 -> 99638.603 | K32: =$B32*(1+K$3/12)^($B$1*12-$A32) -> 151322.33 | L32: =K32+L31 -> 4717813.3 | M32: =K32/((1+'How much will I make'!$C$5/12)^(Calculations!$B$1*12-Calculations!$A32)) -> 23103.673 | N32: =M32+N31 -> 679785.1 | O32: =$B32*(1+O$3/12)^($B$1*12-$A32) -> 968431.38 | P32: =O32+P31 -> 32005591 | Q32: =O32/((1+'How much will I make'!$C$5/12)^(Calculations!$B$1*12-Calculations!$A32)) -> 147858.69 | R32: =Q32+R31 -> 4606507.6 | S32: =$B32*(1+S$3/12)^($B$1*12-$A32) -> 6150883.2 | T32: =S32+T31 -> 2.1566744e+08 | U32: =S32/((1+'How much will I make'!$C$5/12)^(Calculations!$B$1*12-Calculations!$A32)) -> 939107.89 | V32: =U32+V31 -> 31006247 | W32: =$B32*(1+W$3/12)^($B$1*12-$A32) -> 38773567 | X32: =W32+X31 -> 1.4435661e+09 | Y32: =W32/((1+'How much will I make'!$C$5/12)^(Calculations!$B$1*12-Calculations!$A32)) -> 5919891.8 | Z32: =Y32+Z31 -> 2.0731187e+08 | AA32: =$B32*(1+AA$3/12)^($B$1*12-$A32) -> 2.4259968e+08 | AB32: =AA32+AB31 -> 9.598448e+09 | AC32: =AA32/((1+'How much will I make'!$C$5/12)^(Calculations!$B$1*12-Calculations!$A32)) -> 37039766 | AD32: =AC32+AD31 -> 1.3769436e+09 | AE32: =$B32*(1+AE$3/12)^($B$1*12-$A32) -> 1.506701e+09 | AF32: =AE32+AF31 -> 6.3400956e+10 | AG32: =AE32/((1+'How much will I make'!$C$5/12)^(Calculations!$B$1*12-Calculations!$A32)) -> 2.3004092e+08 | AH32: =AG32+AH31 -> 9.0853957e+09
A33: =A32+1 -> 29 | B33: =B32 -> 551.25 | C33: =$B33*(1+$C$3/12)^($B$1*12-$A33) -> 3595.5455 | D33: =C33+D32 -> 104035.97 | E33: =$C33/((1+'How much will I make'!$C$5/12)^(Calculations!$B$1*12-Calculations!$A33)) -> 551.25 | F33: =E33+F32 -> 15056.25 | G33: =$B33*(1+G$3/12)^($B$1*12-$A33) -> 23270.657 | H33: =G33+H32 -> 714001.39 | I33: =G33/((1+'How much will I make'!$C$5/12)^(Calculations!$B$1*12-Calculations!$A33)) -> 3567.7339 | J33: =I33+J32 -> 103206.34 | K33: =$B33*(1+K$3/12)^($B$1*12-$A33) -> 149454.15 | L33: =K33+L32 -> 4867267.5 | M33: =K33/((1+'How much will I make'!$C$5/12)^(Calculations!$B$1*12-Calculations!$A33)) -> 22913.519 | N33: =M33+N32 -> 702698.62 | O33: =$B33*(1+O$3/12)^($B$1*12-$A33) -> 952555.46 | P33: =O33+P32 -> 32958146 | Q33: =O33/((1+'How much will I make'!$C$5/12)^(Calculations!$B$1*12-Calculations!$A33)) -> 146040.76 | R33: =Q33+R32 -> 4752548.4 | S33: =$B33*(1+S$3/12)^($B$1*12-$A33) -> 6025355 | T33: =S33+T32 -> 2.216928e+08 | U33: =S33/((1+'How much will I make'!$C$5/12)^(Calculations!$B$1*12-Calculations!$A33)) -> 923775.52 | V33: =U33+V32 -> 31930023 | W33: =$B33*(1+W$3/12)^($B$1*12-$A33) -> 37827871 | X33: =W33+X32 -> 1.4813939e+09 | Y33: =W33/((1+'How much will I make'!$C$5/12)^(Calculations!$B$1*12-Calculations!$A33)) -> 5799568.8 | Z33: =Y33+Z32 -> 2.1311144e+08 | AA33: =$B33*(1+AA$3/12)^($B$1*12-$A33) -> 2.3572438e+08 | AB33: =AA33+AB32 -> 9.8341724e+09 | AC33: =AA33/((1+'How much will I make'!$C$5/12)^(Calculations!$B$1*12-Calculations!$A33)) -> 36140014 | AD33: =AC33+AD32 -> 1.4130836e+09 | AE33: =$B33*(1+AE$3/12)^($B$1*12-$A33) -> 1.4580978e+09 | AF33: =AE33+AF32 -> 6.4859054e+10 | AG33: =AE33/((1+'How much will I make'!$C$5/12)^(Calculations!$B$1*12-Calculations!$A33)) -> 2.2354783e+08 | AH33: =AG33+AH32 -> 9.3089435e+09
A34: =A33+1 -> 30 | B34: =B33 -> 551.25 | C34: =$B34*(1+$C$3/12)^($B$1*12-$A34) -> 3580.6262 | D34: =C34+D33 -> 107616.59 | E34: =$C34/((1+'How much will I make'!$C$5/12)^(Calculations!$B$1*12-Calculations!$A34)) -> 551.25 | F34: =E34+F33 -> 15607.5 | G34: =$B34*(1+G$3/12)^($B$1*12-$A34) -> 23078.338 | H34: =G34+H33 -> 737079.73 | I34: =G34/((1+'How much will I make'!$C$5/12)^(Calculations!$B$1*12-Calculations!$A34)) -> 3552.9912 | J34: =I34+J33 -> 106759.33 | K34: =$B34*(1+K$3/12)^($B$1*12-$A34) -> 147609.04 | L34: =K34+L33 -> 5014876.5 | M34: =K34/((1+'How much will I make'!$C$5/12)^(Calculations!$B$1*12-Calculations!$A34)) -> 22724.93 | N34: =M34+N33 -> 725423.55 | O34: =$B34*(1+O$3/12)^($B$1*12-$A34) -> 936939.79 | P34: =O34+P33 -> 33895086 | Q34: =O34/((1+'How much will I make'!$C$5/12)^(Calculations!$B$1*12-Calculations!$A34)) -> 144245.18 | R34: =Q34+R33 -> 4896793.5 | S34: =$B34*(1+S$3/12)^($B$1*12-$A34) -> 5902388.6 | T34: =S34+T33 -> 2.2759518e+08 | U34: =S34/((1+'How much will I make'!$C$5/12)^(Calculations!$B$1*12-Calculations!$A34)) -> 908693.47 | V34: =U34+V33 -> 32838716 | W34: =$B34*(1+W$3/12)^($B$1*12-$A34) -> 36905240 | X34: =W34+X33 -> 1.5182992e+09 | Y34: =W34/((1+'How much will I make'!$C$5/12)^(Calculations!$B$1*12-Calculations!$A34)) -> 5681691.4 | Z34: =Y34+Z33 -> 2.1879313e+08 | AA34: =$B34*(1+AA$3/12)^($B$1*12-$A34) -> 2.2904394e+08 | AB34: =AA34+AB33 -> 1.0063216e+10 | AC34: =AA34/((1+'How much will I make'!$C$5/12)^(Calculations!$B$1*12-Calculations!$A34)) -> 35262119 | AD34: =AC34+AD33 -> 1.4483457e+09 | AE34: =$B34*(1+AE$3/12)^($B$1*12-$A34) -> 1.4110623e+09 | AF34: =AE34+AF33 -> 6.6270116e+10 | AG34: =AE34/((1+'How much will I make'!$C$5/12)^(Calculations!$B$1*12-Calculations!$A34)) -> 2.1723801e+08 | AH34: =AG34+AH33 -> 9.5261815e+09
A35: =A34+1 -> 31 | B35: =B34 -> 551.25 | C35: =$B35*(1+$C$3/12)^($B$1*12-$A35) -> 3565.7689 | D35: =C35+D34 -> 111182.36 | E35: =$C35/((1+'How much will I make'!$C$5/12)^(Calculations!$B$1*12-Calculations!$A35)) -> 551.25 | F35: =E35+F34 -> 16158.75 | G35: =$B35*(1+G$3/12)^($B$1*12-$A35) -> 22887.608 | H35: =G35+H34 -> 759967.33 | I35: =G35/((1+'How much will I make'!$C$5/12)^(Calculations!$B$1*12-Calculations!$A35)) -> 3538.3094 | J35: =I35+J34 -> 110297.64 | K35: =$B35*(1+K$3/12)^($B$1*12-$A35) -> 145786.7 | L35: =K35+L34 -> 5160663.2 | M35: =K35/((1+'How much will I make'!$C$5/12)^(Calculations!$B$1*12-Calculations!$A35)) -> 22537.894 | N35: =M35+N34 -> 747961.45 | O35: =$B35*(1+O$3/12)^($B$1*12-$A35) -> 921580.12 | P35: =O35+P34 -> 34816666 | Q35: =O35/((1+'How much will I make'!$C$5/12)^(Calculations!$B$1*12-Calculations!$A35)) -> 142471.67 | R35: =Q35+R34 -> 5039265.2 | S35: =$B35*(1+S$3/12)^($B$1*12-$A35) -> 5781931.7 | T35: =S35+T34 -> 2.3337712e+08 | U35: =S35/((1+'How much will I make'!$C$5/12)^(Calculations!$B$1*12-Calculations!$A35)) -> 893857.66 | V35: =U35+V34 -> 33732574 | W35: =$B35*(1+W$3/12)^($B$1*12-$A35) -> 36005112 | X35: =W35+X34 -> 1.5543043e+09 | Y35: =W35/((1+'How much will I make'!$C$5/12)^(Calculations!$B$1*12-Calculations!$A35)) -> 5566209.9 | Z35: =Y35+Z34 -> 2.2435934e+08 | AA35: =$B35*(1+AA$3/12)^($B$1*12-$A35) -> 2.2255281e+08 | AB35: =AA35+AB34 -> 1.0285769e+10 | AC35: =AA35/((1+'How much will I make'!$C$5/12)^(Calculations!$B$1*12-Calculations!$A35)) -> 34405550 | AD35: =AC35+AD34 -> 1.4827513e+09 | AE35: =$B35*(1+AE$3/12)^($B$1*12-$A35) -> 1.3655442e+09 | AF35: =AE35+AF34 -> 6.763566e+10 | AG35: =AE35/((1+'How much will I make'!$C$5/12)^(Calculations!$B$1*12-Calculations!$A35)) -> 2.1110629e+08 | AH35: =AG35+AH34 -> 9.7372878e+09
