Workbook

Sheet How to use
A1: THIS IS A VIEW-ONLY EXCEL SHEET.
A2: DOWNLOAD THIS SHEET (FILE -> DOWNLOAD AS XLSX) AND THEN USE IT ON YOUR OWN
A4: This sheet has been prepared by Ankur Warikoo, who is NOT a financial advisor :)
A5: So use this sheet with your judgement and not like "this is my final decision"
A7: All cells in green are input cells, which means you have to put in the number
A8: All other cells - ideally you should not touch them. But I have kept them open, so that you can see the formula and how it works
A10: NOTE:
A11: Since I am not a financial advisor, there could be some errors in the sheet. If there are, send me an email and I will fix them. Simple :)
A13: Hope you find this useful.

Sheet Pay off vs Invest
A1: Loan Amount remaining | B1: 1000000
A2: Loan Interest Rate | B2: 0.08
A3: Current month of the loan | B3: 15
A4: Months remaining for the loan | B4: 60
A5: Lumpsum amount you have? | B5: 100000
A6: Amount you can invest every month? | B6: 7000
A7: Return you can generate every year? | B7: 0.1
A9: Over the tenure of your loan
A10: You will pay interest of: | B10: =-CUMIPMT(B2/12,(B3+B4),B1,B3,B4,1) -> 172862.51
A11: You would have invested: | B11: =B5+B6*B4 -> 520000
A12: Your investment would have grown to: | B12: =-FV(B7/12,B4,B6,B5) -> 706590.4
A13: Which means you made an excess of: | B13: =B12-B11 -> 186590.4
A14: This means you should | B14: =IF(B13<B10,"PAY OFF THE LOAN", "INVEST THE AMOUNT") -> INVEST THE AMOUNT

Sheet Calculations
A1: Month | B1: Amount | C1: Return | D1: Total Amount | E1: Inflation adjusted | F1: Total Amount | H1: Lumpsum | I1: Inflation adjusted
A2: 1 | B2: ='Pay off vs Invest'!B6 -> 7000 | C2: =IF(A2<=('Pay off vs Invest'!$B$2-'Pay off vs Invest'!$B$1)*12,Calculations!B2*(1+#REF!/12)^(('Pay off vs Invest'!$B$2-'Pay off vs Invest'!$B$1)*12-A2),0) -> 0 | D2: =SUM(C2:C481) -> 0 | E2: =C2/((1+#REF!/12)^((('Pay off vs Invest'!$B$2-'Pay off vs Invest'!$B$1)*12)-Calculations!A2)) -> #REF! | F2: =SUM(E2:E481) -> #REF! | H2: ='Pay off vs Invest'!B4*(1+#REF!)^(('Pay off vs Invest'!B2-'Pay off vs Invest'!B1)) -> #REF! | I2: =H2/(1+#REF!)^('Pay off vs Invest'!B2-'Pay off vs Invest'!B1) -> #REF!
A3: =A2+1 -> 2 | B3: =B2 -> 7000 | C3: =IF(A3<=('Pay off vs Invest'!$B$2-'Pay off vs Invest'!$B$1)*12,Calculations!B3*(1+#REF!/12)^(('Pay off vs Invest'!$B$2-'Pay off vs Invest'!$B$1)*12-A3),0) -> 0 | E3: =C3/((1+#REF!/12)^((('Pay off vs Invest'!$B$2-'Pay off vs Invest'!$B$1)*12)-Calculations!A3)) -> #REF!
A4: =A3+1 -> 3 | B4: =B3 -> 7000 | C4: =IF(A4<=('Pay off vs Invest'!$B$2-'Pay off vs Invest'!$B$1)*12,Calculations!B4*(1+#REF!/12)^(('Pay off vs Invest'!$B$2-'Pay off vs Invest'!$B$1)*12-A4),0) -> 0 | E4: =C4/((1+#REF!/12)^((('Pay off vs Invest'!$B$2-'Pay off vs Invest'!$B$1)*12)-Calculations!A4)) -> #REF!
A5: =A4+1 -> 4 | B5: =B4 -> 7000 | C5: =IF(A5<=('Pay off vs Invest'!$B$2-'Pay off vs Invest'!$B$1)*12,Calculations!B5*(1+#REF!/12)^(('Pay off vs Invest'!$B$2-'Pay off vs Invest'!$B$1)*12-A5),0) -> 0 | E5: =C5/((1+#REF!/12)^((('Pay off vs Invest'!$B$2-'Pay off vs Invest'!$B$1)*12)-Calculations!A5)) -> #REF!
A6: =A5+1 -> 5 | B6: =B5 -> 7000 | C6: =IF(A6<=('Pay off vs Invest'!$B$2-'Pay off vs Invest'!$B$1)*12,Calculations!B6*(1+#REF!/12)^(('Pay off vs Invest'!$B$2-'Pay off vs Invest'!$B$1)*12-A6),0) -> 0 | E6: =C6/((1+#REF!/12)^((('Pay off vs Invest'!$B$2-'Pay off vs Invest'!$B$1)*12)-Calculations!A6)) -> #REF!
A7: =A6+1 -> 6 | B7: =B6 -> 7000 | C7: =IF(A7<=('Pay off vs Invest'!$B$2-'Pay off vs Invest'!$B$1)*12,Calculations!B7*(1+#REF!/12)^(('Pay off vs Invest'!$B$2-'Pay off vs Invest'!$B$1)*12-A7),0) -> 0 | E7: =C7/((1+#REF!/12)^((('Pay off vs Invest'!$B$2-'Pay off vs Invest'!$B$1)*12)-Calculations!A7)) -> #REF!
A8: =A7+1 -> 7 | B8: =B7 -> 7000 | C8: =IF(A8<=('Pay off vs Invest'!$B$2-'Pay off vs Invest'!$B$1)*12,Calculations!B8*(1+#REF!/12)^(('Pay off vs Invest'!$B$2-'Pay off vs Invest'!$B$1)*12-A8),0) -> 0 | E8: =C8/((1+#REF!/12)^((('Pay off vs Invest'!$B$2-'Pay off vs Invest'!$B$1)*12)-Calculations!A8)) -> #REF!
A9: =A8+1 -> 8 | B9: =B8 -> 7000 | C9: =IF(A9<=('Pay off vs Invest'!$B$2-'Pay off vs Invest'!$B$1)*12,Calculations!B9*(1+#REF!/12)^(('Pay off vs Invest'!$B$2-'Pay off vs Invest'!$B$1)*12-A9),0) -> 0 | E9: =C9/((1+#REF!/12)^((('Pay off vs Invest'!$B$2-'Pay off vs Invest'!$B$1)*12)-Calculations!A9)) -> #REF!
A10: =A9+1 -> 9 | B10: =B9 -> 7000 | C10: =IF(A10<=('Pay off vs Invest'!$B$2-'Pay off vs Invest'!$B$1)*12,Calculations!B10*(1+#REF!/12)^(('Pay off vs Invest'!$B$2-'Pay off vs Invest'!$B$1)*12-A10),0) -> 0 | E10: =C10/((1+#REF!/12)^((('Pay off vs Invest'!$B$2-'Pay off vs Invest'!$B$1)*12)-Calculations!A10)) -> #REF!
A11: =A10+1 -> 10 | B11: =B10 -> 7000 | C11: =IF(A11<=('Pay off vs Invest'!$B$2-'Pay off vs Invest'!$B$1)*12,Calculations!B11*(1+#REF!/12)^(('Pay off vs Invest'!$B$2-'Pay off vs Invest'!$B$1)*12-A11),0) -> 0 | E11: =C11/((1+#REF!/12)^((('Pay off vs Invest'!$B$2-'Pay off vs Invest'!$B$1)*12)-Calculations!A11)) -> #REF!
A12: =A11+1 -> 11 | B12: =B11 -> 7000 | C12: =IF(A12<=('Pay off vs Invest'!$B$2-'Pay off vs Invest'!$B$1)*12,Calculations!B12*(1+#REF!/12)^(('Pay off vs Invest'!$B$2-'Pay off vs Invest'!$B$1)*12-A12),0) -> 0 | E12: =C12/((1+#REF!/12)^((('Pay off vs Invest'!$B$2-'Pay off vs Invest'!$B$1)*12)-Calculations!A12)) -> #REF!
A13: =A12+1 -> 12 | B13: =B12 -> 7000 | C13: =IF(A13<=('Pay off vs Invest'!$B$2-'Pay off vs Invest'!$B$1)*12,Calculations!B13*(1+#REF!/12)^(('Pay off vs Invest'!$B$2-'Pay off vs Invest'!$B$1)*12-A13),0) -> 0 | E13: =C13/((1+#REF!/12)^((('Pay off vs Invest'!$B$2-'Pay off vs Invest'!$B$1)*12)-Calculations!A13)) -> #REF!
A14: =A13+1 -> 13 | B14: =B13*(1+'Pay off vs Invest'!$B$7) -> 7700 | C14: =IF(A14<=('Pay off vs Invest'!$B$2-'Pay off vs Invest'!$B$1)*12,Calculations!B14*(1+#REF!/12)^(('Pay off vs Invest'!$B$2-'Pay off vs Invest'!$B$1)*12-A14),0) -> 0 | E14: =C14/((1+#REF!/12)^((('Pay off vs Invest'!$B$2-'Pay off vs Invest'!$B$1)*12)-Calculations!A14)) -> #REF!
A15: =A14+1 -> 14 | B15: =B14 -> 7700 | C15: =IF(A15<=('Pay off vs Invest'!$B$2-'Pay off vs Invest'!$B$1)*12,Calculations!B15*(1+#REF!/12)^(('Pay off vs Invest'!$B$2-'Pay off vs Invest'!$B$1)*12-A15),0) -> 0 | E15: =C15/((1+#REF!/12)^((('Pay off vs Invest'!$B$2-'Pay off vs Invest'!$B$1)*12)-Calculations!A15)) -> #REF!
A16: =A15+1 -> 15 | B16: =B15 -> 7700 | C16: =IF(A16<=('Pay off vs Invest'!$B$2-'Pay off vs Invest'!$B$1)*12,Calculations!B16*(1+#REF!/12)^(('Pay off vs Invest'!$B$2-'Pay off vs Invest'!$B$1)*12-A16),0) -> 0 | E16: =C16/((1+#REF!/12)^((('Pay off vs Invest'!$B$2-'Pay off vs Invest'!$B$1)*12)-Calculations!A16)) -> #REF!
A17: =A16+1 -> 16 | B17: =B16 -> 7700 | C17: =IF(A17<=('Pay off vs Invest'!$B$2-'Pay off vs Invest'!$B$1)*12,Calculations!B17*(1+#REF!/12)^(('Pay off vs Invest'!$B$2-'Pay off vs Invest'!$B$1)*12-A17),0) -> 0 | E17: =C17/((1+#REF!/12)^((('Pay off vs Invest'!$B$2-'Pay off vs Invest'!$B$1)*12)-Calculations!A17)) -> #REF!
A18: =A17+1 -> 17 | B18: =B17 -> 7700 | C18: =IF(A18<=('Pay off vs Invest'!$B$2-'Pay off vs Invest'!$B$1)*12,Calculations!B18*(1+#REF!/12)^(('Pay off vs Invest'!$B$2-'Pay off vs Invest'!$B$1)*12-A18),0) -> 0 | E18: =C18/((1+#REF!/12)^((('Pay off vs Invest'!$B$2-'Pay off vs Invest'!$B$1)*12)-Calculations!A18)) -> #REF!
A19: =A18+1 -> 18 | B19: =B18 -> 7700 | C19: =IF(A19<=('Pay off vs Invest'!$B$2-'Pay off vs Invest'!$B$1)*12,Calculations!B19*(1+#REF!/12)^(('Pay off vs Invest'!$B$2-'Pay off vs Invest'!$B$1)*12-A19),0) -> 0 | E19: =C19/((1+#REF!/12)^((('Pay off vs Invest'!$B$2-'Pay off vs Invest'!$B$1)*12)-Calculations!A19)) -> #REF!
A20: =A19+1 -> 19 | B20: =B19 -> 7700 | C20: =IF(A20<=('Pay off vs Invest'!$B$2-'Pay off vs Invest'!$B$1)*12,Calculations!B20*(1+#REF!/12)^(('Pay off vs Invest'!$B$2-'Pay off vs Invest'!$B$1)*12-A20),0) -> 0 | E20: =C20/((1+#REF!/12)^((('Pay off vs Invest'!$B$2-'Pay off vs Invest'!$B$1)*12)-Calculations!A20)) -> #REF!
A21: =A20+1 -> 20 | B21: =B20 -> 7700 | C21: =IF(A21<=('Pay off vs Invest'!$B$2-'Pay off vs Invest'!$B$1)*12,Calculations!B21*(1+#REF!/12)^(('Pay off vs Invest'!$B$2-'Pay off vs Invest'!$B$1)*12-A21),0) -> 0 | E21: =C21/((1+#REF!/12)^((('Pay off vs Invest'!$B$2-'Pay off vs Invest'!$B$1)*12)-Calculations!A21)) -> #REF!
A22: =A21+1 -> 21 | B22: =B21 -> 7700 | C22: =IF(A22<=('Pay off vs Invest'!$B$2-'Pay off vs Invest'!$B$1)*12,Calculations!B22*(1+#REF!/12)^(('Pay off vs Invest'!$B$2-'Pay off vs Invest'!$B$1)*12-A22),0) -> 0 | E22: =C22/((1+#REF!/12)^((('Pay off vs Invest'!$B$2-'Pay off vs Invest'!$B$1)*12)-Calculations!A22)) -> #REF!
A23: =A22+1 -> 22 | B23: =B22 -> 7700 | C23: =IF(A23<=('Pay off vs Invest'!$B$2-'Pay off vs Invest'!$B$1)*12,Calculations!B23*(1+#REF!/12)^(('Pay off vs Invest'!$B$2-'Pay off vs Invest'!$B$1)*12-A23),0) -> 0 | E23: =C23/((1+#REF!/12)^((('Pay off vs Invest'!$B$2-'Pay off vs Invest'!$B$1)*12)-Calculations!A23)) -> #REF!
A24: =A23+1 -> 23 | B24: =B23 -> 7700 | C24: =IF(A24<=('Pay off vs Invest'!$B$2-'Pay off vs Invest'!$B$1)*12,Calculations!B24*(1+#REF!/12)^(('Pay off vs Invest'!$B$2-'Pay off vs Invest'!$B$1)*12-A24),0) -> 0 | E24: =C24/((1+#REF!/12)^((('Pay off vs Invest'!$B$2-'Pay off vs Invest'!$B$1)*12)-Calculations!A24)) -> #REF!
A25: =A24+1 -> 24 | B25: =B24 -> 7700 | C25: =IF(A25<=('Pay off vs Invest'!$B$2-'Pay off vs Invest'!$B$1)*12,Calculations!B25*(1+#REF!/12)^(('Pay off vs Invest'!$B$2-'Pay off vs Invest'!$B$1)*12-A25),0) -> 0 | E25: =C25/((1+#REF!/12)^((('Pay off vs Invest'!$B$2-'Pay off vs Invest'!$B$1)*12)-Calculations!A25)) -> #REF!
A26: =A25+1 -> 25 | B26: =B25*(1+'Pay off vs Invest'!$B$7) -> 8470 | C26: =IF(A26<=('Pay off vs Invest'!$B$2-'Pay off vs Invest'!$B$1)*12,Calculations!B26*(1+#REF!/12)^(('Pay off vs Invest'!$B$2-'Pay off vs Invest'!$B$1)*12-A26),0) -> 0 | E26: =C26/((1+#REF!/12)^((('Pay off vs Invest'!$B$2-'Pay off vs Invest'!$B$1)*12)-Calculations!A26)) -> #REF!
A27: =A26+1 -> 26 | B27: =B26 -> 8470 | C27: =IF(A27<=('Pay off vs Invest'!$B$2-'Pay off vs Invest'!$B$1)*12,Calculations!B27*(1+#REF!/12)^(('Pay off vs Invest'!$B$2-'Pay off vs Invest'!$B$1)*12-A27),0) -> 0 | E27: =C27/((1+#REF!/12)^((('Pay off vs Invest'!$B$2-'Pay off vs Invest'!$B$1)*12)-Calculations!A27)) -> #REF!
A28: =A27+1 -> 27 | B28: =B27 -> 8470 | C28: =IF(A28<=('Pay off vs Invest'!$B$2-'Pay off vs Invest'!$B$1)*12,Calculations!B28*(1+#REF!/12)^(('Pay off vs Invest'!$B$2-'Pay off vs Invest'!$B$1)*12-A28),0) -> 0 | E28: =C28/((1+#REF!/12)^((('Pay off vs Invest'!$B$2-'Pay off vs Invest'!$B$1)*12)-Calculations!A28)) -> #REF!
A29: =A28+1 -> 28 | B29: =B28 -> 8470 | C29: =IF(A29<=('Pay off vs Invest'!$B$2-'Pay off vs Invest'!$B$1)*12,Calculations!B29*(1+#REF!/12)^(('Pay off vs Invest'!$B$2-'Pay off vs Invest'!$B$1)*12-A29),0) -> 0 | E29: =C29/((1+#REF!/12)^((('Pay off vs Invest'!$B$2-'Pay off vs Invest'!$B$1)*12)-Calculations!A29)) -> #REF!
A30: =A29+1 -> 29 | B30: =B29 -> 8470 | C30: =IF(A30<=('Pay off vs Invest'!$B$2-'Pay off vs Invest'!$B$1)*12,Calculations!B30*(1+#REF!/12)^(('Pay off vs Invest'!$B$2-'Pay off vs Invest'!$B$1)*12-A30),0) -> 0 | E30: =C30/((1+#REF!/12)^((('Pay off vs Invest'!$B$2-'Pay off vs Invest'!$B$1)*12)-Calculations!A30)) -> #REF!
A31: =A30+1 -> 30 | B31: =B30 -> 8470 | C31: =IF(A31<=('Pay off vs Invest'!$B$2-'Pay off vs Invest'!$B$1)*12,Calculations!B31*(1+#REF!/12)^(('Pay off vs Invest'!$B$2-'Pay off vs Invest'!$B$1)*12-A31),0) -> 0 | E31: =C31/((1+#REF!/12)^((('Pay off vs Invest'!$B$2-'Pay off vs Invest'!$B$1)*12)-Calculations!A31)) -> #REF!
A32: =A31+1 -> 31 | B32: =B31 -> 8470 | C32: =IF(A32<=('Pay off vs Invest'!$B$2-'Pay off vs Invest'!$B$1)*12,Calculations!B32*(1+#REF!/12)^(('Pay off vs Invest'!$B$2-'Pay off vs Invest'!$B$1)*12-A32),0) -> 0 | E32: =C32/((1+#REF!/12)^((('Pay off vs Invest'!$B$2-'Pay off vs Invest'!$B$1)*12)-Calculations!A32)) -> #REF!
A33: =A32+1 -> 32 | B33: =B32 -> 8470 | C33: =IF(A33<=('Pay off vs Invest'!$B$2-'Pay off vs Invest'!$B$1)*12,Calculations!B33*(1+#REF!/12)^(('Pay off vs Invest'!$B$2-'Pay off vs Invest'!$B$1)*12-A33),0) -> 0 | E33: =C33/((1+#REF!/12)^((('Pay off vs Invest'!$B$2-'Pay off vs Invest'!$B$1)*12)-Calculations!A33)) -> #REF!
A34: =A33+1 -> 33 | B34: =B33 -> 8470 | C34: =IF(A34<=('Pay off vs Invest'!$B$2-'Pay off vs Invest'!$B$1)*12,Calculations!B34*(1+#REF!/12)^(('Pay off vs Invest'!$B$2-'Pay off vs Invest'!$B$1)*12-A34),0) -> 0 | E34: =C34/((1+#REF!/12)^((('Pay off vs Invest'!$B$2-'Pay off vs Invest'!$B$1)*12)-Calculations!A34)) -> #REF!
A35: =A34+1 -> 34 | B35: =B34 -> 8470 | C35: =IF(A35<=('Pay off vs Invest'!$B$2-'Pay off vs Invest'!$B$1)*12,Calculations!B35*(1+#REF!/12)^(('Pay off vs Invest'!$B$2-'Pay off vs Invest'!$B$1)*12-A35),0) -> 0 | E35: =C35/((1+#REF!/12)^((('Pay off vs Invest'!$B$2-'Pay off vs Invest'!$B$1)*12)-Calculations!A35)) -> #REF!
A36: =A35+1 -> 35 | B36: =B35 -> 8470 | C36: =IF(A36<=('Pay off vs Invest'!$B$2-'Pay off vs Invest'!$B$1)*12,Calculations!B36*(1+#REF!/12)^(('Pay off vs Invest'!$B$2-'Pay off vs Invest'!$B$1)*12-A36),0) -> 0 | E36: =C36/((1+#REF!/12)^((('Pay off vs Invest'!$B$2-'Pay off vs Invest'!$B$1)*12)-Calculations!A36)) -> #REF!
A37: =A36+1 -> 36 | B37: =B36 -> 8470 | C37: =IF(A37<=('Pay off vs Invest'!$B$2-'Pay off vs Invest'!$B$1)*12,Calculations!B37*(1+#REF!/12)^(('Pay off vs Invest'!$B$2-'Pay off vs Invest'!$B$1)*12-A37),0) -> 0 | E37: =C37/((1+#REF!/12)^((('Pay off vs Invest'!$B$2-'Pay off vs Invest'!$B$1)*12)-Calculations!A37)) -> #REF!
A38: =A37+1 -> 37 | B38: =B37*(1+'Pay off vs Invest'!$B$7) -> 9317 | C38: =IF(A38<=('Pay off vs Invest'!$B$2-'Pay off vs Invest'!$B$1)*12,Calculations!B38*(1+#REF!/12)^(('Pay off vs Invest'!$B$2-'Pay off vs Invest'!$B$1)*12-A38),0) -> 0 | E38: =C38/((1+#REF!/12)^((('Pay off vs Invest'!$B$2-'Pay off vs Invest'!$B$1)*12)-Calculations!A38)) -> #REF!
A39: =A38+1 -> 38 | B39: =B38 -> 9317 | C39: =IF(A39<=('Pay off vs Invest'!$B$2-'Pay off vs Invest'!$B$1)*12,Calculations!B39*(1+#REF!/12)^(('Pay off vs Invest'!$B$2-'Pay off vs Invest'!$B$1)*12-A39),0) -> 0 | E39: =C39/((1+#REF!/12)^((('Pay off vs Invest'!$B$2-'Pay off vs Invest'!$B$1)*12)-Calculations!A39)) -> #REF!
A40: =A39+1 -> 39 | B40: =B39 -> 9317 | C40: =IF(A40<=('Pay off vs Invest'!$B$2-'Pay off vs Invest'!$B$1)*12,Calculations!B40*(1+#REF!/12)^(('Pay off vs Invest'!$B$2-'Pay off vs Invest'!$B$1)*12-A40),0) -> 0 | E40: =C40/((1+#REF!/12)^((('Pay off vs Invest'!$B$2-'Pay off vs Invest'!$B$1)*12)-Calculations!A40)) -> #REF!
...
